Workbook
Name PERFORMANCETASKS: '[1]INPUT DATA'!#REF!
Name PERFORMANCETASKS: '[2]INPUT DATA'!#REF!
Name PERFORMANCETASKS: '[2]INPUT DATA'!#REF!
Name PT: '[1]INPUT DATA'!#REF!
Name PT: '[2]INPUT DATA'!#REF!
Name PT: '[2]INPUT DATA'!#REF!
Name QA: '[1]INPUT DATA'!#REF!
Name QA: '[2]INPUT DATA'!#REF!
Name QA: '[2]INPUT DATA'!#REF!
Name QUARTERLYASSESSMENT: '[1]INPUT DATA'!#REF!
Name QUARTERLYASSESSMENT: '[2]INPUT DATA'!#REF!
Name QUARTERLYASSESSMENT: '[2]INPUT DATA'!#REF!
Name SUBJECTS: '[3]INPUT DATA'!$A$1002:$A$1005
Name Transmu_Table: '[1]INPUT DATA'!#REF!
Name Transmu_Table: '[2]INPUT DATA'!#REF!
Name TRANSMUTATION_TABLE: '[4]DO NOT DELETE'!$G$2:$J$42
Name TRANSMUTATION_TABLE: '[5]DO NOT DELETE'!$G$2:$J$42
Name TRANSMUTATION_TABLE: 'DO NOT DELETE'!$G$2:$J$42
Name TRANSMUTATION_TABLE_2: '[6]DO NOT DELETE'!$G$2:$J$42
Name WRITTENWORKS: '[1]INPUT DATA'!#REF!
Name WRITTENWORKS: '[2]INPUT DATA'!#REF!
Name WW: '[1]INPUT DATA'!#REF!
Name WW: '[2]INPUT DATA'!#REF!

Sheet INPUT DATA
A1: Input Data Sheet for E-Class Record | AL1: Validation | AM1: Subject | AN1: ID
AL2: Generated thru SilVerLab | AM2: Mathematics | AN2: fd9e83b9-50fb-427a-a0db-0874e42f3a81
C4: REGION | G4: RIX | L4: DIVISION | O4: Zamboanga Del Norte | T4: DISTRICT | X4: Salug I
B5: SCHOOL NAME | G5: Salug National High School | T5: SCHOOL ID | X5: 303721 | AD5: SCHOOL YEAR | AG5: 2026-2027
F7: GRADE & SECTION: | K7: CSS 9 - Rizal | Q7: TEACHER: | S7: Kho, Teacher | AC7: SUBJECT: | AG7: CSS 9
B8: LEARNERS' NAMES
B11: MALE
A12: 1 | B12: BAYETA, PAUL
A13: 2 | B13: BOGANUTAN, ROLAND
A14: 3 | B14: BONTIGAO, CLYDE
A15: 4 | B15: CABARDO, JOEREN DAVE
A16: 5 | B16: CASTILLO, Z-JOHN
A17: 6 | B17: ELOG, DENIEL JAY
A18: 7 | B18: JUMALON, JANLEOVIR
A19: 8 | B19: MONSALUD, REY
A20: 9 | B20: PATAGOC, DENIEL
A21: 10 | B21: QUIPOT, LICH JAY
A22: 11 | B22: RAYNO, VINCENT
A23: 12 | B23: RIBO, KIMHAR
... A32: 21 | B32: VASQUEZ, FRENZ ANTHONY
A33: 22
A34: 23
A35: 24
A36: 25
A37: 26
A38: 27
A39: 28
A40: 29
A41: 30
A42: 31
A43: 32
A44: 33
... A71: 60
B72: FEMALE
A73: 1 | B73: AMANDORON, NATHALIE
A74: 2 | B74: BAGUIO, SCARLET JANE
A75: 3 | B75: BAYNAS, AMIE JEAN
A76: 4 | B76: CABALLETE, GWEN TIFFANY
A77: 5 | B77: DELICANO, EJ MAE
A78: 6 | B78: DIJINO, PRINCESS JILL
...

Sheet Table
B2: TRANSMUTATION TABLE | H2: Descriptive Ratings | O2: Outstanding | S2: 90-100
B3: 0 | C3: - | D3: 24.99 | E3: 60 | H3: 0 | I3: 64 | J3: Emerging (Nasisimula) | O3: Very Satisfactory | S3: 85-89
B4: 25 | C4: - | D4: 39.99 | E4: 60 | H4: 65 | I4: 74 | J4: Developing (Napauunlad) | O4: Satisfactory | S4: 80-84
B5: 40 | C5: - | D5: 42.99 | E5: 61 | H5: 75 | I5: 79 | J5: Connecting (Natutungo) | O5: Fairly Satisfactory | S5: 75-79
B6: 43 | C6: - | D6: 45.99 | E6: 62 | H6: 80 | I6: 89 | J6: Benchmarking (Napamamalas) | O6: Did Not Meet Expectations | S6: Below 75
B7: 46 | C7: - | D7: 47.99 | E7: 63 | H7: 90 | I7: 100 | J7: Advancing (Namumukod-tangi)
B8: 48 | C8: - | D8: 49.99 | E8: 64
B9: 50 | C9: - | D9: 51.99 | E9: 65
B10: 52 | C10: - | D10: 53.99 | E10: 66
B11: 54 | C11: - | D11: 55.99 | E11: 67 | H11: Letter Grade
B12: 56 | C12: - | D12: 57.99 | E12: 68 | H12: 0 | I12: 64 | J12: E
B13: 58 | C13: - | D13: 59.99 | E13: 69 | H13: 65 | I13: 74 | J13: D
B14: 60 | C14: - | D14: 61.99 | E14: 70 | H14: 75 | I14: 79 | J14: C
B15: 62 | C15: - | D15: 63.99 | E15: 71 | H15: 80 | I15: 89 | J15: B
B16: 64 | C16: - | D16: 65.99 | E16: 72 | H16: 90 | I16: 100 | J16: A
B17: 66 | C17: - | D17: 67.99 | E17: 73
B18: 68 | C18: - | D18: 69.99 | E18: 74
B19: 70 | C19: - | D19: 72.99 | E19: 75
B20: 73 | C20: - | D20: 74.99 | E20: 76
B21: 75 | C21: - | D21: 75.99 | E21: 77
B22: 76 | C22: - | D22: 76.99 | E22: 78
B23: 77 | C23: - | D23: 77.99 | E23: 79
B24: 78 | C24: - | D24: 78.99 | E24: 80
B25: 79 | C25: - | D25: 79.99 | E25: 81
B26: 80 | C26: - | D26: 80.99 | E26: 82
B27: 81 | C27: - | D27: 81.99 | E27: 83
B28: 82 | C28: - | D28: 82.99 | E28: 84
... B44: 99.5 | C44: - | D44: 100 | E44: 100

Sheet Term 1
A1: Class Record | AS1: LRN
A3: (Pursuant to Deped Order 8 series of 2015)
C4: REGION | G4: ='INPUT DATA'!G4 -> IX | L4: DIVISION | O4: ='INPUT DATA'!O4 -> Schools Division of Zamboanga del Norte | T4: DISTRICT | X4: ='INPUT DATA'!X4 -> 0
B5: SCHOOL NAME | G5: ='INPUT DATA'!G5 -> 0 | T5: SCHOOL ID | X5: ='INPUT DATA'!X5 -> 0 | AD5: SCHOOL YEAR | AM5: ='INPUT DATA'!AG5 -> 0
A7: Term 1 | F7: GRADE & SECTION: | K7: ='INPUT DATA'!K7 -> 0 | Q7: TEACHER: | S7: ='INPUT DATA'!S7 -> 0 | AC7: SUBJECT: | AM7: ='INPUT DATA'!AG7 -> 0
B8: LEARNERS' NAMES | F8: WRITTEN WORKS (20%) | S8: PERFORMANCE TASKS (60%) | AF8: Summative and Term Examination (20%) | AO8: Initial Grade | AP8: Term Grade | AQ8: Letter Grade | AR8: Descriptive Rating
F9: 1 | G9: 2 | H9: 3 | I9: 4 | J9: 5 | K9: 6 | L9: 7 | M9: 8 | N9: 9 | O9: 10 | P9: Total | Q9: PS | R9: WS | S9: 1 | T9: 2 | U9: 3 | V9: 4 | W9: 5 | X9: 6 | Y9: 7 | Z9: 8 | AA9: 9 | AB9: 10 | AC9: Total | AD9: PS | AE9: WS | AF9: ST1 | AG9: WS1 | AH9: ST2 | AI9: WS2 | AJ9: TE | AK9: WST | AL9: Total | AM9: PS | AN9: WS
B10: HIGHEST POSSIBLE SCORE | P10: =IF(COUNT($F10:$O10)=0,"",SUM($F10:$O10)) | Q10: 100 | R10: 0.2 | AC10: =IF(COUNT($S10:$AB10)=0,"",SUM($S10:$AB10)) | AD10: 100 | AE10: 0.6 | AG10: 30 | AI10: 30 | AK10: 40 | AL10: =IF(COUNT(AF10:AJ10)=0,"",SUM(AF10:AJ10)) -> 60 | AM10: 100 | AN10: 0.2
B11: MALE
A12: 1 | B12: ='INPUT DATA'!B12 -> 0 | P12: =IF(COUNT($F12:$O12)=0,"",SUM($F12:$O12)) | Q12: =IF(ISERROR(IF($P12="","",ROUND(($P12/$P$10)*$Q$10,2))),"",IF($P12="","",ROUND(($P12/$P$10)*$Q$10,2))) | R12: =IF($Q12="","",ROUND($Q12*$R$10,2)) | AC12: =IF(COUNT($S12:$AB12)=0,"",SUM($S12:$AB12)) | AD12: =IF(ISERROR(IF($AC12="","",ROUND(($AC12/$AC$10)*$AD$10,2))),"",IF($AC12="","",ROUND(($AC12/$AC$10)*$AD$10,2))) | AE12: =IF($AD12="","",ROUND($AD12*$AE$10,2)) | AG12: =IF(ISBLANK(AF12),"",(AF12/$AF$10)*$AG$10) | AI12: =IF(ISBLANK(AH12),"",(AH12/$AH$10)*$AI$10) | AK12: =IF(ISBLANK(AJ12),"",(AJ12/$AJ$10)*$AK$10) | AL12: =IF(COUNTA(AF12,AH12,AJ12),AF12+AH12+AJ12,"") | AM12: =IFERROR(IF(COUNTA(AG12,AI12,AK12),(AG12+AI12+AK12),""),"") | AN12: =IF($AM12="","",ROUND($AM12*$AN$10,2)) | AO12: =IF(ISERROR(IF($AN12="","",ROUND(SUM($R12,$AE12,$AN12),2))),"",IF($AN12="","",ROUND(SUM($R12,$AE12,$AN12),2))) | AP12: =IF(ISERROR(IF($AO12="","",VLOOKUP(AO12,Table!$B$3:$E$44,4,TRUE))),"",IF($AO12="","",VLOOKUP(AO12,Table!$B$3:$E$44,4,TRUE))) | AQ12: =IF(ISERROR(IF($AP12="","",VLOOKUP(AP12,Table!$H$12:$J$16,3,TRUE))),"",IF($AP12="","",VLOOKUP(AP12,Table!$H$12:$J$16,3,TRUE))) | AR12: =IF(AP12="","",VLOOKUP(ROUND(AP12,0),Table!$H$3:$J$7,3,TRUE)) | AS12: 124623170080
A13: 2 | B13: ='INPUT DATA'!B13 -> 0 | P13: =IF(COUNT($F13:$O13)=0,"",SUM($F13:$O13)) | Q13: =IF(ISERROR(IF($P13="","",ROUND(($P13/$P$10)*$Q$10,2))),"",IF($P13="","",ROUND(($P13/$P$10)*$Q$10,2))) | R13: =IF($Q13="","",ROUND($Q13*$R$10,2)) | AC13: =IF(COUNT($S13:$AB13)=0,"",SUM($S13:$AB13)) | AD13: =IF(ISERROR(IF($AC13="","",ROUND(($AC13/$AC$10)*$AD$10,2))),"",IF($AC13="","",ROUND(($AC13/$AC$10)*$AD$10,2))) | AE13: =IF($AD13="","",ROUND($AD13*$AE$10,2)) | AG13: =IF(ISBLANK(AF13),"",(AF13/$AF$10)*$AG$10) | AI13: =IF(ISBLANK(AH13),"",(AH13/$AH$10)*$AI$10) | AK13: =IF(ISBLANK(AJ13),"",(AJ13/$AJ$10)*$AK$10) | AL13: =IF(COUNTA(AF13,AH13,AJ13),AF13+AH13+AJ13,"") | AM13: =IFERROR(IF(COUNTA(AG13,AI13,AK13),(AG13+AI13+AK13),""),"") | AN13: =IF($AM13="","",ROUND($AM13*$AN$10,2)) | AO13: =IF(ISERROR(IF($AN13="","",ROUND(SUM($R13,$AE13,$AN13),2))),"",IF($AN13="","",ROUND(SUM($R13,$AE13,$AN13),2))) | AP13: =IF(ISERROR(IF($AO13="","",VLOOKUP(AO13,Table!$B$3:$E$44,4,TRUE))),"",IF($AO13="","",VLOOKUP(AO13,Table!$B$3:$E$44,4,TRUE))) | AQ13: =IF(ISERROR(IF($AP13="","",VLOOKUP(AP13,Table!$H$12:$J$16,3,TRUE))),"",IF($AP13="","",VLOOKUP(AP13,Table!$H$12:$J$16,3,TRUE))) | AR13: =IF(AP13="","",VLOOKUP(ROUND(AP13,0),Table!$H$3:$J$7,3,TRUE)) | AS13: 124623170082
A14: 3 | B14: ='INPUT DATA'!B14 -> 0 | P14: =IF(COUNT($F14:$O14)=0,"",SUM($F14:$O14)) | Q14: =IF(ISERROR(IF($P14="","",ROUND(($P14/$P$10)*$Q$10,2))),"",IF($P14="","",ROUND(($P14/$P$10)*$Q$10,2))) | R14: =IF($Q14="","",ROUND($Q14*$R$10,2)) | AC14: =IF(COUNT($S14:$AB14)=0,"",SUM($S14:$AB14)) | AD14: =IF(ISERROR(IF($AC14="","",ROUND(($AC14/$AC$10)*$AD$10,2))),"",IF($AC14="","",ROUND(($AC14/$AC$10)*$AD$10,2))) | AE14: =IF($AD14="","",ROUND($AD14*$AE$10,2)) | AG14: =IF(ISBLANK(AF14),"",(AF14/$AF$10)*$AG$10) | AI14: =IF(ISBLANK(AH14),"",(AH14/$AH$10)*$AI$10) | AK14: =IF(ISBLANK(AJ14),"",(AJ14/$AJ$10)*$AK$10) | AL14: =IF(COUNTA(AF14,AH14,AJ14),AF14+AH14+AJ14,"") | AM14: =IFERROR(IF(COUNTA(AG14,AI14,AK14),(AG14+AI14+AK14),""),"") | AN14: =IF($AM14="","",ROUND($AM14*$AN$10,2)) | AO14: =IF(ISERROR(IF($AN14="","",ROUND(SUM($R14,$AE14,$AN14),2))),"",IF($AN14="","",ROUND(SUM($R14,$AE14,$AN14),2))) | AP14: =IF(ISERROR(IF($AO14="","",VLOOKUP(AO14,Table!$B$3:$E$44,4,TRUE))),"",IF($AO14="","",VLOOKUP(AO14,Table!$B$3:$E$44,4,TRUE))) | AQ14: =IF(ISERROR(IF($AP14="","",VLOOKUP(AP14,Table!$H$12:$J$16,3,TRUE))),"",IF($AP14="","",VLOOKUP(AP14,Table!$H$12:$J$16,3,TRUE))) | AR14: =IF(AP14="","",VLOOKUP(ROUND(AP14,0),Table!$H$3:$J$7,3,TRUE)) | AS14: 124623160139
A15: 4 | B15: ='INPUT DATA'!B15 -> 0 | P15: =IF(COUNT($F15:$O15)=0,"",SUM($F15:$O15)) | Q15: =IF(ISERROR(IF($P15="","",ROUND(($P15/$P$10)*$Q$10,2))),"",IF($P15="","",ROUND(($P15/$P$10)*$Q$10,2))) | R15: =IF($Q15="","",ROUND($Q15*$R$10,2)) | AC15: =IF(COUNT($S15:$AB15)=0,"",SUM($S15:$AB15)) | AD15: =IF(ISERROR(IF($AC15="","",ROUND(($AC15/$AC$10)*$AD$10,2))),"",IF($AC15="","",ROUND(($AC15/$AC$10)*$AD$10,2))) | AE15: =IF($AD15="","",ROUND($AD15*$AE$10,2)) | AG15: =IF(ISBLANK(AF15),"",(AF15/$AF$10)*$AG$10) | AI15: =IF(ISBLANK(AH15),"",(AH15/$AH$10)*$AI$10) | AK15: =IF(ISBLANK(AJ15),"",(AJ15/$AJ$10)*$AK$10) | AL15: =IF(COUNTA(AF15,AH15,AJ15),AF15+AH15+AJ15,"") | AM15: =IFERROR(IF(COUNTA(AG15,AI15,AK15),(AG15+AI15+AK15),""),"") | AN15: =IF($AM15="","",ROUND($AM15*$AN$10,2)) | AO15: =IF(ISERROR(IF($AN15="","",ROUND(SUM($R15,$AE15,$AN15),2))),"",IF($AN15="","",ROUND(SUM($R15,$AE15,$AN15),2))) | AP15: =IF(ISERROR(IF($AO15="","",VLOOKUP(AO15,Table!$B$3:$E$44,4,TRUE))),"",IF($AO15="","",VLOOKUP(AO15,Table!$B$3:$E$44,4,TRUE))) | AQ15: =IF(ISERROR(IF($AP15="","",VLOOKUP(AP15,Table!$H$12:$J$16,3,TRUE))),"",IF($AP15="","",VLOOKUP(AP15,Table!$H$12:$J$16,3,TRUE))) | AR15: =IF(AP15="","",VLOOKUP(ROUND(AP15,0),Table!$H$3:$J$7,3,TRUE)) | AS15: 125785170007
A16: 5 | B16: ='INPUT DATA'!B16 -> 0 | P16: =IF(COUNT($F16:$O16)=0,"",SUM($F16:$O16)) | Q16: =IF(ISERROR(IF($P16="","",ROUND(($P16/$P$10)*$Q$10,2))),"",IF($P16="","",ROUND(($P16/$P$10)*$Q$10,2))) | R16: =IF($Q16="","",ROUND($Q16*$R$10,2)) | AC16: =IF(COUNT($S16:$AB16)=0,"",SUM($S16:$AB16)) | AD16: =IF(ISERROR(IF($AC16="","",ROUND(($AC16/$AC$10)*$AD$10,2))),"",IF($AC16="","",ROUND(($AC16/$AC$10)*$AD$10,2))) | AE16: =IF($AD16="","",ROUND($AD16*$AE$10,2)) | AG16: =IF(ISBLANK(AF16),"",(AF16/$AF$10)*$AG$10) | AI16: =IF(ISBLANK(AH16),"",(AH16/$AH$10)*$AI$10) | AK16: =IF(ISBLANK(AJ16),"",(AJ16/$AJ$10)*$AK$10) | AL16: =IF(COUNTA(AF16,AH16,AJ16),AF16+AH16+AJ16,"") | AM16: =IFERROR(IF(COUNTA(AG16,AI16,AK16),(AG16+AI16+AK16),""),"") | AN16: =IF($AM16="","",ROUND($AM16*$AN$10,2)) | AO16: =IF(ISERROR(IF($AN16="","",ROUND(SUM($R16,$AE16,$AN16),2))),"",IF($AN16="","",ROUND(SUM($R16,$AE16,$AN16),2))) | AP16: =IF(ISERROR(IF($AO16="","",VLOOKUP(AO16,Table!$B$3:$E$44,4,TRUE))),"",IF($AO16="","",VLOOKUP(AO16,Table!$B$3:$E$44,4,TRUE))) | AQ16: =IF(ISERROR(IF($AP16="","",VLOOKUP(AP16,Table!$H$12:$J$16,3,TRUE))),"",IF($AP16="","",VLOOKUP(AP16,Table!$H$12:$J$16,3,TRUE))) | AR16: =IF(AP16="","",VLOOKUP(ROUND(AP16,0),Table!$H$3:$J$7,3,TRUE)) | AS16: 124628170031
A17: 6 | B17: ='INPUT DATA'!B17 -> 0 | P17: =IF(COUNT($F17:$O17)=0,"",SUM($F17:$O17)) | Q17: =IF(ISERROR(IF($P17="","",ROUND(($P17/$P$10)*$Q$10,2))),"",IF($P17="","",ROUND(($P17/$P$10)*$Q$10,2))) | R17: =IF($Q17="","",ROUND($Q17*$R$10,2)) | AC17: =IF(COUNT($S17:$AB17)=0,"",SUM($S17:$AB17)) | AD17: =IF(ISERROR(IF($AC17="","",ROUND(($AC17/$AC$10)*$AD$10,2))),"",IF($AC17="","",ROUND(($AC17/$AC$10)*$AD$10,2))) | AE17: =IF($AD17="","",ROUND($AD17*$AE$10,2)) | AG17: =IF(ISBLANK(AF17),"",(AF17/$AF$10)*$AG$10) | AI17: =IF(ISBLANK(AH17),"",(AH17/$AH$10)*$AI$10) | AK17: =IF(ISBLANK(AJ17),"",(AJ17/$AJ$10)*$AK$10) | AL17: =IF(COUNTA(AF17,AH17,AJ17),AF17+AH17+AJ17,"") | AM17: =IFERROR(IF(COUNTA(AG17,AI17,AK17),(AG17+AI17+AK17),""),"") | AN17: =IF($AM17="","",ROUND($AM17*$AN$10,2)) | AO17: =IF(ISERROR(IF($AN17="","",ROUND(SUM($R17,$AE17,$AN17),2))),"",IF($AN17="","",ROUND(SUM($R17,$AE17,$AN17),2))) | AP17: =IF(ISERROR(IF($AO17="","",VLOOKUP(AO17,Table!$B$3:$E$44,4,TRUE))),"",IF($AO17="","",VLOOKUP(AO17,Table!$B$3:$E$44,4,TRUE))) | AQ17: =IF(ISERROR(IF($AP17="","",VLOOKUP(AP17,Table!$H$12:$J$16,3,TRUE))),"",IF($AP17="","",VLOOKUP(AP17,Table!$H$12:$J$16,3,TRUE))) | AR17: =IF(AP17="","",VLOOKUP(ROUND(AP17,0),Table!$H$3:$J$7,3,TRUE)) | AS17: 12427570007
A18: 7 | B18: ='INPUT DATA'!B18 -> 0 | P18: =IF(COUNT($F18:$O18)=0,"",SUM($F18:$O18)) | Q18: =IF(ISERROR(IF($P18="","",ROUND(($P18/$P$10)*$Q$10,2))),"",IF($P18="","",ROUND(($P18/$P$10)*$Q$10,2))) | R18: =IF($Q18="","",ROUND($Q18*$R$10,2)) | AC18: =IF(COUNT($S18:$AB18)=0,"",SUM($S18:$AB18)) | AD18: =IF(ISERROR(IF($AC18="","",ROUND(($AC18/$AC$10)*$AD$10,2))),"",IF($AC18="","",ROUND(($AC18/$AC$10)*$AD$10,2))) | AE18: =IF($AD18="","",ROUND($AD18*$AE$10,2)) | AG18: =IF(ISBLANK(AF18),"",(AF18/$AF$10)*$AG$10) | AI18: =IF(ISBLANK(AH18),"",(AH18/$AH$10)*$AI$10) | AK18: =IF(ISBLANK(AJ18),"",(AJ18/$AJ$10)*$AK$10) | AL18: =IF(COUNTA(AF18,AH18,AJ18),AF18+AH18+AJ18,"") | AM18: =IFERROR(IF(COUNTA(AG18,AI18,AK18),(AG18+AI18+AK18),""),"") | AN18: =IF($AM18="","",ROUND($AM18*$AN$10,2)) | AO18: =IF(ISERROR(IF($AN18="","",ROUND(SUM($R18,$AE18,$AN18),2))),"",IF($AN18="","",ROUND(SUM($R18,$AE18,$AN18),2))) | AP18: =IF(ISERROR(IF($AO18="","",VLOOKUP(AO18,Table!$B$3:$E$44,4,TRUE))),"",IF($AO18="","",VLOOKUP(AO18,Table!$B$3:$E$44,4,TRUE))) | AQ18: =IF(ISERROR(IF($AP18="","",VLOOKUP(AP18,Table!$H$12:$J$16,3,TRUE))),"",IF($AP18="","",VLOOKUP(AP18,Table!$H$12:$J$16,3,TRUE))) | AR18: =IF(AP18="","",VLOOKUP(ROUND(AP18,0),Table!$H$3:$J$7,3,TRUE)) | AS18: 124625150005
A19: 8 | B19: ='INPUT DATA'!B19 -> 0 | D19: 0 | P19: =IF(COUNT($F19:$O19)=0,"",SUM($F19:$O19)) | Q19: =IF(ISERROR(IF($P19="","",ROUND(($P19/$P$10)*$Q$10,2))),"",IF($P19="","",ROUND(($P19/$P$10)*$Q$10,2))) | R19: =IF($Q19="","",ROUND($Q19*$R$10,2)) | AC19: =IF(COUNT($S19:$AB19)=0,"",SUM($S19:$AB19)) | AD19: =IF(ISERROR(IF($AC19="","",ROUND(($AC19/$AC$10)*$AD$10,2))),"",IF($AC19="","",ROUND(($AC19/$AC$10)*$AD$10,2))) | AE19: =IF($AD19="","",ROUND($AD19*$AE$10,2)) | AG19: =IF(ISBLANK(AF19),"",(AF19/$AF$10)*$AG$10) | AI19: =IF(ISBLANK(AH19),"",(AH19/$AH$10)*$AI$10) | AK19: =IF(ISBLANK(AJ19),"",(AJ19/$AJ$10)*$AK$10) | AL19: =IF(COUNTA(AF19,AH19,AJ19),AF19+AH19+AJ19,"") | AM19: =IFERROR(IF(COUNTA(AG19,AI19,AK19),(AG19+AI19+AK19),""),"") | AN19: =IF($AM19="","",ROUND($AM19*$AN$10,2)) | AO19: =IF(ISERROR(IF($AN19="","",ROUND(SUM($R19,$AE19,$AN19),2))),"",IF($AN19="","",ROUND(SUM($R19,$AE19,$AN19),2))) | AP19: =IF(ISERROR(IF($AO19="","",VLOOKUP(AO19,Table!$B$3:$E$44,4,TRUE))),"",IF($AO19="","",VLOOKUP(AO19,Table!$B$3:$E$44,4,TRUE))) | AQ19: =IF(ISERROR(IF($AP19="","",VLOOKUP(AP19,Table!$H$12:$J$16,3,TRUE))),"",IF($AP19="","",VLOOKUP(AP19,Table!$H$12:$J$16,3,TRUE))) | AR19: =IF(AP19="","",VLOOKUP(ROUND(AP19,0),Table!$H$3:$J$7,3,TRUE)) | AS19: 124628160034
A20: 9 | B20: ='INPUT DATA'!B20 -> 0 | P20: =IF(COUNT($F20:$O20)=0,"",SUM($F20:$O20)) | Q20: =IF(ISERROR(IF($P20="","",ROUND(($P20/$P$10)*$Q$10,2))),"",IF($P20="","",ROUND(($P20/$P$10)*$Q$10,2))) | R20: =IF($Q20="","",ROUND($Q20*$R$10,2)) | AC20: =IF(COUNT($S20:$AB20)=0,"",SUM($S20:$AB20)) | AD20: =IF(ISERROR(IF($AC20="","",ROUND(($AC20/$AC$10)*$AD$10,2))),"",IF($AC20="","",ROUND(($AC20/$AC$10)*$AD$10,2))) | AE20: =IF($AD20="","",ROUND($AD20*$AE$10,2)) | AG20: =IF(ISBLANK(AF20),"",(AF20/$AF$10)*$AG$10) | AI20: =IF(ISBLANK(AH20),"",(AH20/$AH$10)*$AI$10) | AK20: =IF(ISBLANK(AJ20),"",(AJ20/$AJ$10)*$AK$10) | AL20: =IF(COUNTA(AF20,AH20,AJ20),AF20+AH20+AJ20,"") | AM20: =IFERROR(IF(COUNTA(AG20,AI20,AK20),(AG20+AI20+AK20),""),"") | AN20: =IF($AM20="","",ROUND($AM20*$AN$10,2)) | AO20: =IF(ISERROR(IF($AN20="","",ROUND(SUM($R20,$AE20,$AN20),2))),"",IF($AN20="","",ROUND(SUM($R20,$AE20,$AN20),2))) | AP20: =IF(ISERROR(IF($AO20="","",VLOOKUP(AO20,Table!$B$3:$E$44,4,TRUE))),"",IF($AO20="","",VLOOKUP(AO20,Table!$B$3:$E$44,4,TRUE))) | AQ20: =IF(ISERROR(IF($AP20="","",VLOOKUP(AP20,Table!$H$12:$J$16,3,TRUE))),"",IF($AP20="","",VLOOKUP(AP20,Table!$H$12:$J$16,3,TRUE))) | AR20: =IF(AP20="","",VLOOKUP(ROUND(AP20,0),Table!$H$3:$J$7,3,TRUE)) | AS20: 124623150072
A21: 10 | B21: ='INPUT DATA'!B21 -> 0 | P21: =IF(COUNT($F21:$O21)=0,"",SUM($F21:$O21)) | Q21: =IF(ISERROR(IF($P21="","",ROUND(($P21/$P$10)*$Q$10,2))),"",IF($P21="","",ROUND(($P21/$P$10)*$Q$10,2))) | R21: =IF($Q21="","",ROUND($Q21*$R$10,2)) | AC21: =IF(COUNT($S21:$AB21)=0,"",SUM($S21:$AB21)) | AD21: =IF(ISERROR(IF($AC21="","",ROUND(($AC21/$AC$10)*$AD$10,2))),"",IF($AC21="","",ROUND(($AC21/$AC$10)*$AD$10,2))) | AE21: =IF($AD21="","",ROUND($AD21*$AE$10,2)) | AG21: =IF(ISBLANK(AF21),"",(AF21/$AF$10)*$AG$10) | AI21: =IF(ISBLANK(AH21),"",(AH21/$AH$10)*$AI$10) | AK21: =IF(ISBLANK(AJ21),"",(AJ21/$AJ$10)*$AK$10) | AL21: =IF(COUNTA(AF21,AH21,AJ21),AF21+AH21+AJ21,"") | AM21: =IFERROR(IF(COUNTA(AG21,AI21,AK21),(AG21+AI21+AK21),""),"") | AN21: =IF($AM21="","",ROUND($AM21*$AN$10,2)) | AO21: =IF(ISERROR(IF($AN21="","",ROUND(SUM($R21,$AE21,$AN21),2))),"",IF($AN21="","",ROUND(SUM($R21,$AE21,$AN21),2))) | AP21: =IF(ISERROR(IF($AO21="","",VLOOKUP(AO21,Table!$B$3:$E$44,4,TRUE))),"",IF($AO21="","",VLOOKUP(AO21,Table!$B$3:$E$44,4,TRUE))) | AQ21: =IF(ISERROR(IF($AP21="","",VLOOKUP(AP21,Table!$H$12:$J$16,3,TRUE))),"",IF($AP21="","",VLOOKUP(AP21,Table!$H$12:$J$16,3,TRUE))) | AR21: =IF(AP21="","",VLOOKUP(ROUND(AP21,0),Table!$H$3:$J$7,3,TRUE)) | AS21: 124623170177
A22: 11 | B22: ='INPUT DATA'!B22 -> 0 | D22: 0 | P22: =IF(COUNT($F22:$O22)=0,"",SUM($F22:$O22)) | Q22: =IF(ISERROR(IF($P22="","",ROUND(($P22/$P$10)*$Q$10,2))),"",IF($P22="","",ROUND(($P22/$P$10)*$Q$10,2))) | R22: =IF($Q22="","",ROUND($Q22*$R$10,2)) | AC22: =IF(COUNT($S22:$AB22)=0,"",SUM($S22:$AB22)) | AD22: =IF(ISERROR(IF($AC22="","",ROUND(($AC22/$AC$10)*$AD$10,2))),"",IF($AC22="","",ROUND(($AC22/$AC$10)*$AD$10,2))) | AE22: =IF($AD22="","",ROUND($AD22*$AE$10,2)) | AG22: =IF(ISBLANK(AF22),"",(AF22/$AF$10)*$AG$10) | AI22: =IF(ISBLANK(AH22),"",(AH22/$AH$10)*$AI$10) | AK22: =IF(ISBLANK(AJ22),"",(AJ22/$AJ$10)*$AK$10) | AL22: =IF(COUNTA(AF22,AH22,AJ22),AF22+AH22+AJ22,"") | AM22: =IFERROR(IF(COUNTA(AG22,AI22,AK22),(AG22+AI22+AK22),""),"") | AN22: =IF($AM22="","",ROUND($AM22*$AN$10,2)) | AO22: =IF(ISERROR(IF($AN22="","",ROUND(SUM($R22,$AE22,$AN22),2))),"",IF($AN22="","",ROUND(SUM($R22,$AE22,$AN22),2))) | AP22: =IF(ISERROR(IF($AO22="","",VLOOKUP(AO22,Table!$B$3:$E$44,4,TRUE))),"",IF($AO22="","",VLOOKUP(AO22,Table!$B$3:$E$44,4,TRUE))) | AQ22: =IF(ISERROR(IF($AP22="","",VLOOKUP(AP22,Table!$H$12:$J$16,3,TRUE))),"",IF($AP22="","",VLOOKUP(AP22,Table!$H$12:$J$16,3,TRUE))) | AR22: =IF(AP22="","",VLOOKUP(ROUND(AP22,0),Table!$H$3:$J$7,3,TRUE)) | AS22: 124628160014
A23: 12 | B23: ='INPUT DATA'!B23 -> 0 | P23: =IF(COUNT($F23:$O23)=0,"",SUM($F23:$O23)) | Q23: =IF(ISERROR(IF($P23="","",ROUND(($P23/$P$10)*$Q$10,2))),"",IF($P23="","",ROUND(($P23/$P$10)*$Q$10,2))) | R23: =IF($Q23="","",ROUND($Q23*$R$10,2)) | AC23: =IF(COUNT($S23:$AB23)=0,"",SUM($S23:$AB23)) | AD23: =IF(ISERROR(IF($AC23="","",ROUND(($AC23/$AC$10)*$AD$10,2))),"",IF($AC23="","",ROUND(($AC23/$AC$10)*$AD$10,2))) | AE23: =IF($AD23="","",ROUND($AD23*$AE$10,2)) | AG23: =IF(ISBLANK(AF23),"",(AF23/$AF$10)*$AG$10) | AI23: =IF(ISBLANK(AH23),"",(AH23/$AH$10)*$AI$10) | AK23: =IF(ISBLANK(AJ23),"",(AJ23/$AJ$10)*$AK$10) | AL23: =IF(COUNTA(AF23,AH23,AJ23),AF23+AH23+AJ23,"") | AM23: =IFERROR(IF(COUNTA(AG23,AI23,AK23),(AG23+AI23+AK23),""),"") | AN23: =IF($AM23="","",ROUND($AM23*$AN$10,2)) | AO23: =IF(ISERROR(IF($AN23="","",ROUND(SUM($R23,$AE23,$AN23),2))),"",IF($AN23="","",ROUND(SUM($R23,$AE23,$AN23),2))) | AP23: =IF(ISERROR(IF($AO23="","",VLOOKUP(AO23,Table!$B$3:$E$44,4,TRUE))),"",IF($AO23="","",VLOOKUP(AO23,Table!$B$3:$E$44,4,TRUE))) | AQ23: =IF(ISERROR(IF($AP23="","",VLOOKUP(AP23,Table!$H$12:$J$16,3,TRUE))),"",IF($AP23="","",VLOOKUP(AP23,Table!$H$12:$J$16,3,TRUE))) | AR23: =IF(AP23="","",VLOOKUP(ROUND(AP23,0),Table!$H$3:$J$7,3,TRUE)) | AS23: 124616170003
A24: 13 | B24: ='INPUT DATA'!B24 -> 0 | P24: =IF(COUNT($F24:$O24)=0,"",SUM($F24:$O24)) | Q24: =IF(ISERROR(IF($P24="","",ROUND(($P24/$P$10)*$Q$10,2))),"",IF($P24="","",ROUND(($P24/$P$10)*$Q$10,2))) | R24: =IF($Q24="","",ROUND($Q24*$R$10,2)) | AC24: =IF(COUNT($S24:$AB24)=0,"",SUM($S24:$AB24)) | AD24: =IF(ISERROR(IF($AC24="","",ROUND(($AC24/$AC$10)*$AD$10,2))),"",IF($AC24="","",ROUND(($AC24/$AC$10)*$AD$10,2))) | AE24: =IF($AD24="","",ROUND($AD24*$AE$10,2)) | AG24: =IF(ISBLANK(AF24),"",(AF24/$AF$10)*$AG$10) | AI24: =IF(ISBLANK(AH24),"",(AH24/$AH$10)*$AI$10) | AK24: =IF(ISBLANK(AJ24),"",(AJ24/$AJ$10)*$AK$10) | AL24: =IF(COUNTA(AF24,AH24,AJ24),AF24+AH24+AJ24,"") | AM24: =IFERROR(IF(COUNTA(AG24,AI24,AK24),(AG24+AI24+AK24),""),"") | AN24: =IF($AM24="","",ROUND($AM24*$AN$10,2)) | AO24: =IF(ISERROR(IF($AN24="","",ROUND(SUM($R24,$AE24,$AN24),2))),"",IF($AN24="","",ROUND(SUM($R24,$AE24,$AN24),2))) | AP24: =IF(ISERROR(IF($AO24="","",VLOOKUP(AO24,Table!$B$3:$E$44,4,TRUE))),"",IF($AO24="","",VLOOKUP(AO24,Table!$B$3:$E$44,4,TRUE))) | AQ24: =IF(ISERROR(IF($AP24="","",VLOOKUP(AP24,Table!$H$12:$J$16,3,TRUE))),"",IF($AP24="","",VLOOKUP(AP24,Table!$H$12:$J$16,3,TRUE))) | AR24: =IF(AP24="","",VLOOKUP(ROUND(AP24,0),Table!$H$3:$J$7,3,TRUE)) | AS24: 124628160037
A25: 14 | B25: ='INPUT DATA'!B25 -> 0 | P25: =IF(COUNT($F25:$O25)=0,"",SUM($F25:$O25)) | Q25: =IF(ISERROR(IF($P25="","",ROUND(($P25/$P$10)*$Q$10,2))),"",IF($P25="","",ROUND(($P25/$P$10)*$Q$10,2))) | R25: =IF($Q25="","",ROUND($Q25*$R$10,2)) | AC25: =IF(COUNT($S25:$AB25)=0,"",SUM($S25:$AB25)) | AD25: =IF(ISERROR(IF($AC25="","",ROUND(($AC25/$AC$10)*$AD$10,2))),"",IF($AC25="","",ROUND(($AC25/$AC$10)*$AD$10,2))) | AE25: =IF($AD25="","",ROUND($AD25*$AE$10,2)) | AG25: =IF(ISBLANK(AF25),"",(AF25/$AF$10)*$AG$10) | AI25: =IF(ISBLANK(AH25),"",(AH25/$AH$10)*$AI$10) | AK25: =IF(ISBLANK(AJ25),"",(AJ25/$AJ$10)*$AK$10) | AL25: =IF(COUNTA(AF25,AH25,AJ25),AF25+AH25+AJ25,"") | AM25: =IFERROR(IF(COUNTA(AG25,AI25,AK25),(AG25+AI25+AK25),""),"") | AN25: =IF($AM25="","",ROUND($AM25*$AN$10,2)) | AO25: =IF(ISERROR(IF($AN25="","",ROUND(SUM($R25,$AE25,$AN25),2))),"",IF($AN25="","",ROUND(SUM($R25,$AE25,$AN25),2))) | AP25: =IF(ISERROR(IF($AO25="","",VLOOKUP(AO25,Table!$B$3:$E$44,4,TRUE))),"",IF($AO25="","",VLOOKUP(AO25,Table!$B$3:$E$44,4,TRUE))) | AQ25: =IF(ISERROR(IF($AP25="","",VLOOKUP(AP25,Table!$H$12:$J$16,3,TRUE))),"",IF($AP25="","",VLOOKUP(AP25,Table!$H$12:$J$16,3,TRUE))) | AR25: =IF(AP25="","",VLOOKUP(ROUND(AP25,0),Table!$H$3:$J$7,3,TRUE)) | AS25: 124623170062
A26: 15 | B26: ='INPUT DATA'!B26 -> 0 | P26: =IF(COUNT($F26:$O26)=0,"",SUM($F26:$O26)) | Q26: =IF(ISERROR(IF($P26="","",ROUND(($P26/$P$10)*$Q$10,2))),"",IF($P26="","",ROUND(($P26/$P$10)*$Q$10,2))) | R26: =IF($Q26="","",ROUND($Q26*$R$10,2)) | AC26: =IF(COUNT($S26:$AB26)=0,"",SUM($S26:$AB26)) | AD26: =IF(ISERROR(IF($AC26="","",ROUND(($AC26/$AC$10)*$AD$10,2))),"",IF($AC26="","",ROUND(($AC26/$AC$10)*$AD$10,2))) | AE26: =IF($AD26="","",ROUND($AD26*$AE$10,2)) | AG26: =IF(ISBLANK(AF26),"",(AF26/$AF$10)*$AG$10) | AI26: =IF(ISBLANK(AH26),"",(AH26/$AH$10)*$AI$10) | AK26: =IF(ISBLANK(AJ26),"",(AJ26/$AJ$10)*$AK$10) | AL26: =IF(COUNTA(AF26,AH26,AJ26),AF26+AH26+AJ26,"") | AM26: =IFERROR(IF(COUNTA(AG26,AI26,AK26),(AG26+AI26+AK26),""),"") | AN26: =IF($AM26="","",ROUND($AM26*$AN$10,2)) | AO26: =IF(ISERROR(IF($AN26="","",ROUND(SUM($R26,$AE26,$AN26),2))),"",IF($AN26="","",ROUND(SUM($R26,$AE26,$AN26),2))) | AP26: =IF(ISERROR(IF($AO26="","",VLOOKUP(AO26,Table!$B$3:$E$44,4,TRUE))),"",IF($AO26="","",VLOOKUP(AO26,Table!$B$3:$E$44,4,TRUE))) | AQ26: =IF(ISERROR(IF($AP26="","",VLOOKUP(AP26,Table!$H$12:$J$16,3,TRUE))),"",IF($AP26="","",VLOOKUP(AP26,Table!$H$12:$J$16,3,TRUE))) | AR26: =IF(AP26="","",VLOOKUP(ROUND(AP26,0),Table!$H$3:$J$7,3,TRUE)) | AS26: 124616170007
A27: 16 | B27: ='INPUT DATA'!B27 -> 0 | P27: =IF(COUNT($F27:$O27)=0,"",SUM($F27:$O27)) | Q27: =IF(ISERROR(IF($P27="","",ROUND(($P27/$P$10)*$Q$10,2))),"",IF($P27="","",ROUND(($P27/$P$10)*$Q$10,2))) | R27: =IF($Q27="","",ROUND($Q27*$R$10,2)) | AC27: =IF(COUNT($S27:$AB27)=0,"",SUM($S27:$AB27)) | AD27: =IF(ISERROR(IF($AC27="","",ROUND(($AC27/$AC$10)*$AD$10,2))),"",IF($AC27="","",ROUND(($AC27/$AC$10)*$AD$10,2))) | AE27: =IF($AD27="","",ROUND($AD27*$AE$10,2)) | AG27: =IF(ISBLANK(AF27),"",(AF27/$AF$10)*$AG$10) | AI27: =IF(ISBLANK(AH27),"",(AH27/$AH$10)*$AI$10) | AK27: =IF(ISBLANK(AJ27),"",(AJ27/$AJ$10)*$AK$10) | AL27: =IF(COUNTA(AF27,AH27,AJ27),AF27+AH27+AJ27,"") | AM27: =IFERROR(IF(COUNTA(AG27,AI27,AK27),(AG27+AI27+AK27),""),"") | AN27: =IF($AM27="","",ROUND($AM27*$AN$10,2)) | AO27: =IF(ISERROR(IF($AN27="","",ROUND(SUM($R27,$AE27,$AN27),2))),"",IF($AN27="","",ROUND(SUM($R27,$AE27,$AN27),2))) | AP27: =IF(ISERROR(IF($AO27="","",VLOOKUP(AO27,Table!$B$3:$E$44,4,TRUE))),"",IF($AO27="","",VLOOKUP(AO27,Table!$B$3:$E$44,4,TRUE))) | AQ27: =IF(ISERROR(IF($AP27="","",VLOOKUP(AP27,Table!$H$12:$J$16,3,TRUE))),"",IF($AP27="","",VLOOKUP(AP27,Table!$H$12:$J$16,3,TRUE))) | AR27: =IF(AP27="","",VLOOKUP(ROUND(AP27,0),Table!$H$3:$J$7,3,TRUE)) | AS27: 124620160006
A28: 17 | B28: ='INPUT DATA'!B28 -> 0 | P28: =IF(COUNT($F28:$O28)=0,"",SUM($F28:$O28)) | Q28: =IF(ISERROR(IF($P28="","",ROUND(($P28/$P$10)*$Q$10,2))),"",IF($P28="","",ROUND(($P28/$P$10)*$Q$10,2))) | R28: =IF($Q28="","",ROUND($Q28*$R$10,2)) | AC28: =IF(COUNT($S28:$AB28)=0,"",SUM($S28:$AB28)) | AD28: =IF(ISERROR(IF($AC28="","",ROUND(($AC28/$AC$10)*$AD$10,2))),"",IF($AC28="","",ROUND(($AC28/$AC$10)*$AD$10,2))) | AE28: =IF($AD28="","",ROUND($AD28*$AE$10,2)) | AG28: =IF(ISBLANK(AF28),"",(AF28/$AF$10)*$AG$10) | AI28: =IF(ISBLANK(AH28),"",(AH28/$AH$10)*$AI$10) | AK28: =IF(ISBLANK(AJ28),"",(AJ28/$AJ$10)*$AK$10) | AL28: =IF(COUNTA(AF28,AH28,AJ28),AF28+AH28+AJ28,"") | AM28: =IFERROR(IF(COUNTA(AG28,AI28,AK28),(AG28+AI28+AK28),""),"") | AN28: =IF($AM28="","",ROUND($AM28*$AN$10,2)) | AO28: =IF(ISERROR(IF($AN28="","",ROUND(SUM($R28,$AE28,$AN28),2))),"",IF($AN28="","",ROUND(SUM($R28,$AE28,$AN28),2))) | AP28: =IF(ISERROR(IF($AO28="","",VLOOKUP(AO28,Table!$B$3:$E$44,4,TRUE))),"",IF($AO28="","",VLOOKUP(AO28,Table!$B$3:$E$44,4,TRUE))) | AQ28: =IF(ISERROR(IF($AP28="","",VLOOKUP(AP28,Table!$H$12:$J$16,3,TRUE))),"",IF($AP28="","",VLOOKUP(AP28,Table!$H$12:$J$16,3,TRUE))) | AR28: =IF(AP28="","",VLOOKUP(ROUND(AP28,0),Table!$H$3:$J$7,3,TRUE)) | AS28: 124622170008
A29: 18 | B29: ='INPUT DATA'!B29 -> 0 | P29: =IF(COUNT($F29:$O29)=0,"",SUM($F29:$O29)) | Q29: =IF(ISERROR(IF($P29="","",ROUND(($P29/$P$10)*$Q$10,2))),"",IF($P29="","",ROUND(($P29/$P$10)*$Q$10,2))) | R29: =IF($Q29="","",ROUND($Q29*$R$10,2)) | AC29: =IF(COUNT($S29:$AB29)=0,"",SUM($S29:$AB29)) | AD29: =IF(ISERROR(IF($AC29="","",ROUND(($AC29/$AC$10)*$AD$10,2))),"",IF($AC29="","",ROUND(($AC29/$AC$10)*$AD$10,2))) | AE29: =IF($AD29="","",ROUND($AD29*$AE$10,2)) | AG29: =IF(ISBLANK(AF29),"",(AF29/$AF$10)*$AG$10) | AI29: =IF(ISBLANK(AH29),"",(AH29/$AH$10)*$AI$10) | AK29: =IF(ISBLANK(AJ29),"",(AJ29/$AJ$10)*$AK$10) | AL29: =IF(COUNTA(AF29,AH29,AJ29),AF29+AH29+AJ29,"") | AM29: =IFERROR(IF(COUNTA(AG29,AI29,AK29),(AG29+AI29+AK29),""),"") | AN29: =IF($AM29="","",ROUND($AM29*$AN$10,2)) | AO29: =IF(ISERROR(IF($AN29="","",ROUND(SUM($R29,$AE29,$AN29),2))),"",IF($AN29="","",ROUND(SUM($R29,$AE29,$AN29),2))) | AP29: =IF(ISERROR(IF($AO29="","",VLOOKUP(AO29,Table!$B$3:$E$44,4,TRUE))),"",IF($AO29="","",VLOOKUP(AO29,Table!$B$3:$E$44,4,TRUE))) | AQ29: =IF(ISERROR(IF($AP29="","",VLOOKUP(AP29,Table!$H$12:$J$16,3,TRUE))),"",IF($AP29="","",VLOOKUP(AP29,Table!$H$12:$J$16,3,TRUE))) | AR29: =IF(AP29="","",VLOOKUP(ROUND(AP29,0),Table!$H$3:$J$7,3,TRUE)) | AS29: 124623170035
A30: 19 | B30: ='INPUT DATA'!B30 -> 0 | P30: =IF(COUNT($F30:$O30)=0,"",SUM($F30:$O30)) | Q30: =IF(ISERROR(IF($P30="","",ROUND(($P30/$P$10)*$Q$10,2))),"",IF($P30="","",ROUND(($P30/$P$10)*$Q$10,2))) | R30: =IF($Q30="","",ROUND($Q30*$R$10,2)) | AC30: =IF(COUNT($S30:$AB30)=0,"",SUM($S30:$AB30)) | AD30: =IF(ISERROR(IF($AC30="","",ROUND(($AC30/$AC$10)*$AD$10,2))),"",IF($AC30="","",ROUND(($AC30/$AC$10)*$AD$10,2))) | AE30: =IF($AD30="","",ROUND($AD30*$AE$10,2)) | AG30: =IF(ISBLANK(AF30),"",(AF30/$AF$10)*$AG$10) | AI30: =IF(ISBLANK(AH30),"",(AH30/$AH$10)*$AI$10) | AK30: =IF(ISBLANK(AJ30),"",(AJ30/$AJ$10)*$AK$10) | AL30: =IF(COUNTA(AF30,AH30,AJ30),AF30+AH30+AJ30,"") | AM30: =IFERROR(IF(COUNTA(AG30,AI30,AK30),(AG30+AI30+AK30),""),"") | AN30: =IF($AM30="","",ROUND($AM30*$AN$10,2)) | AO30: =IF(ISERROR(IF($AN30="","",ROUND(SUM($R30,$AE30,$AN30),2))),"",IF($AN30="","",ROUND(SUM($R30,$AE30,$AN30),2))) | AP30: =IF(ISERROR(IF($AO30="","",VLOOKUP(AO30,Table!$B$3:$E$44,4,TRUE))),"",IF($AO30="","",VLOOKUP(AO30,Table!$B$3:$E$44,4,TRUE))) | AQ30: =IF(ISERROR(IF($AP30="","",VLOOKUP(AP30,Table!$H$12:$J$16,3,TRUE))),"",IF($AP30="","",VLOOKUP(AP30,Table!$H$12:$J$16,3,TRUE))) | AR30: =IF(AP30="","",VLOOKUP(ROUND(AP30,0),Table!$H$3:$J$7,3,TRUE)) | AS30: 124620170005
A31: 20 | B31: ='INPUT DATA'!B31 -> 0 | P31: =IF(COUNT($F31:$O31)=0,"",SUM($F31:$O31)) | Q31: =IF(ISERROR(IF($P31="","",ROUND(($P31/$P$10)*$Q$10,2))),"",IF($P31="","",ROUND(($P31/$P$10)*$Q$10,2))) | R31: =IF($Q31="","",ROUND($Q31*$R$10,2)) | AC31: =IF(COUNT($S31:$AB31)=0,"",SUM($S31:$AB31)) | AD31: =IF(ISERROR(IF($AC31="","",ROUND(($AC31/$AC$10)*$AD$10,2))),"",IF($AC31="","",ROUND(($AC31/$AC$10)*$AD$10,2))) | AE31: =IF($AD31="","",ROUND($AD31*$AE$10,2)) | AG31: =IF(ISBLANK(AF31),"",(AF31/$AF$10)*$AG$10) | AI31: =IF(ISBLANK(AH31),"",(AH31/$AH$10)*$AI$10) | AK31: =IF(ISBLANK(AJ31),"",(AJ31/$AJ$10)*$AK$10) | AL31: =IF(COUNTA(AF31,AH31,AJ31),AF31+AH31+AJ31,"") | AM31: =IFERROR(IF(COUNTA(AG31,AI31,AK31),(AG31+AI31+AK31),""),"") | AN31: =IF($AM31="","",ROUND($AM31*$AN$10,2)) | AO31: =IF(ISERROR(IF($AN31="","",ROUND(SUM($R31,$AE31,$AN31),2))),"",IF($AN31="","",ROUND(SUM($R31,$AE31,$AN31),2))) | AP31: =IF(ISERROR(IF($AO31="","",VLOOKUP(AO31,Table!$B$3:$E$44,4,TRUE))),"",IF($AO31="","",VLOOKUP(AO31,Table!$B$3:$E$44,4,TRUE))) | AQ31: =IF(ISERROR(IF($AP31="","",VLOOKUP(AP31,Table!$H$12:$J$16,3,TRUE))),"",IF($AP31="","",VLOOKUP(AP31,Table!$H$12:$J$16,3,TRUE))) | AR31: =IF(AP31="","",VLOOKUP(ROUND(AP31,0),Table!$H$3:$J$7,3,TRUE)) | AS31: 124623170064
A32: 21 | B32: ='INPUT DATA'!B32 -> 0 | P32: =IF(COUNT($F32:$O32)=0,"",SUM($F32:$O32)) | Q32: =IF(ISERROR(IF($P32="","",ROUND(($P32/$P$10)*$Q$10,2))),"",IF($P32="","",ROUND(($P32/$P$10)*$Q$10,2))) | R32: =IF($Q32="","",ROUND($Q32*$R$10,2)) | AC32: =IF(COUNT($S32:$AB32)=0,"",SUM($S32:$AB32)) | AD32: =IF(ISERROR(IF($AC32="","",ROUND(($AC32/$AC$10)*$AD$10,2))),"",IF($AC32="","",ROUND(($AC32/$AC$10)*$AD$10,2))) | AE32: =IF($AD32="","",ROUND($AD32*$AE$10,2)) | AG32: =IF(ISBLANK(AF32),"",(AF32/$AF$10)*$AG$10) | AI32: =IF(ISBLANK(AH32),"",(AH32/$AH$10)*$AI$10) | AK32: =IF(ISBLANK(AJ32),"",(AJ32/$AJ$10)*$AK$10) | AL32: =IF(COUNTA(AF32,AH32,AJ32),AF32+AH32+AJ32,"") | AM32: =IFERROR(IF(COUNTA(AG32,AI32,AK32),(AG32+AI32+AK32),""),"") | AN32: =IF($AM32="","",ROUND($AM32*$AN$10,2)) | AO32: =IF(ISERROR(IF($AN32="","",ROUND(SUM($R32,$AE32,$AN32),2))),"",IF($AN32="","",ROUND(SUM($R32,$AE32,$AN32),2))) | AP32: =IF(ISERROR(IF($AO32="","",VLOOKUP(AO32,Table!$B$3:$E$44,4,TRUE))),"",IF($AO32="","",VLOOKUP(AO32,Table!$B$3:$E$44,4,TRUE))) | AQ32: =IF(ISERROR(IF($AP32="","",VLOOKUP(AP32,Table!$H$12:$J$16,3,TRUE))),"",IF($AP32="","",VLOOKUP(AP32,Table!$H$12:$J$16,3,TRUE))) | AR32: =IF(AP32="","",VLOOKUP(ROUND(AP32,0),Table!$H$3:$J$7,3,TRUE)) | AS32: 124623170169
A33: 22 | B33: ='INPUT DATA'!B33 -> 0 | P33: =IF(COUNT($F33:$O33)=0,"",SUM($F33:$O33)) | Q33: =IF(ISERROR(IF($P33="","",ROUND(($P33/$P$10)*$Q$10,2))),"",IF($P33="","",ROUND(($P33/$P$10)*$Q$10,2))) | R33: =IF($Q33="","",ROUND($Q33*$R$10,2)) | AC33: =IF(COUNT($S33:$AB33)=0,"",SUM($S33:$AB33)) | AD33: =IF(ISERROR(IF($AC33="","",ROUND(($AC33/$AC$10)*$AD$10,2))),"",IF($AC33="","",ROUND(($AC33/$AC$10)*$AD$10,2))) | AE33: =IF($AD33="","",ROUND($AD33*$AE$10,2)) | AG33: =IF(ISBLANK(AF33),"",(AF33/$AF$10)*$AG$10) | AI33: =IF(ISBLANK(AH33),"",(AH33/$AH$10)*$AI$10) | AK33: =IF(ISBLANK(AJ33),"",(AJ33/$AJ$10)*$AK$10) | AL33: =IF(COUNTA(AF33,AH33,AJ33),AF33+AH33+AJ33,"") | AM33: =IFERROR(IF(COUNTA(AG33,AI33,AK33),(AG33+AI33+AK33),""),"") | AN33: =IF($AM33="","",ROUND($AM33*$AN$10,2)) | AO33: =IF(ISERROR(IF($AN33="","",ROUND(SUM($R33,$AE33,$AN33),2))),"",IF($AN33="","",ROUND(SUM($R33,$AE33,$AN33),2))) | AP33: =IF(ISERROR(IF($AO33="","",VLOOKUP(AO33,Table!$B$3:$E$44,4,TRUE))),"",IF($AO33="","",VLOOKUP(AO33,Table!$B$3:$E$44,4,TRUE))) | AQ33: =IF(ISERROR(IF($AP33="","",VLOOKUP(AP33,Table!$H$12:$J$16,3,TRUE))),"",IF($AP33="","",VLOOKUP(AP33,Table!$H$12:$J$16,3,TRUE))) | AR33: =IF(AP33="","",VLOOKUP(ROUND(AP33,0),Table!$H$3:$J$7,3,TRUE)) | AS33: 124627170021
A34: 23 | B34: ='INPUT DATA'!B34 -> 0 | P34: =IF(COUNT($F34:$O34)=0,"",SUM($F34:$O34)) | Q34: =IF(ISERROR(IF($P34="","",ROUND(($P34/$P$10)*$Q$10,2))),"",IF($P34="","",ROUND(($P34/$P$10)*$Q$10,2))) | R34: =IF($Q34="","",ROUND($Q34*$R$10,2)) | AC34: =IF(COUNT($S34:$AB34)=0,"",SUM($S34:$AB34)) | AD34: =IF(ISERROR(IF($AC34="","",ROUND(($AC34/$AC$10)*$AD$10,2))),"",IF($AC34="","",ROUND(($AC34/$AC$10)*$AD$10,2))) | AE34: =IF($AD34="","",ROUND($AD34*$AE$10,2)) | AL34: =IF(COUNT(AF34:AJ34)=0,"",SUM(AF34:AJ34)) | AM34: =IF(ISERROR(IF($AL34="","",ROUND(($AL34/$AL$10)*$AM$10,2))),"",IF($AL34="","",ROUND(($AL34/$AL$10)*$AM$10,2))) | AN34: =IF($AM34="","",ROUND($AM34*$AN$10,2)) | AO34: =IF(ISERROR(IF($AN34="","",ROUND(SUM($R34,$AE34,$AN34),2))),"",IF($AN34="","",ROUND(SUM($R34,$AE34,$AN34),2))) | AP34: =IF(ISERROR(IF($AO34="","",VLOOKUP(AO34,Table!$B$3:$E$44,4,TRUE))),"",IF($AO34="","",VLOOKUP(AO34,Table!$B$3:$E$44,4,TRUE))) | AQ34: =IF(ISERROR(IF($AP34="","",VLOOKUP(AP34,Table!$H$12:$J$16,3,TRUE))),"",IF($AP34="","",VLOOKUP(AP34,Table!$H$12:$J$16,3,TRUE))) | AR34: =IF(AP34="","",VLOOKUP(ROUND(AP34,0),Table!$H$3:$J$7,3,TRUE))
A35: 24 | B35: ='INPUT DATA'!B35 -> 0 | P35: =IF(COUNT($F35:$O35)=0,"",SUM($F35:$O35)) | Q35: =IF(ISERROR(IF($P35="","",ROUND(($P35/$P$10)*$Q$10,2))),"",IF($P35="","",ROUND(($P35/$P$10)*$Q$10,2))) | R35: =IF($Q35="","",ROUND($Q35*$R$10,2)) | AC35: =IF(COUNT($S35:$AB35)=0,"",SUM($S35:$AB35)) | AD35: =IF(ISERROR(IF($AC35="","",ROUND(($AC35/$AC$10)*$AD$10,2))),"",IF($AC35="","",ROUND(($AC35/$AC$10)*$AD$10,2))) | AE35: =IF($AD35="","",ROUND($AD35*$AE$10,2)) | AL35: =IF(COUNT(AF35:AJ35)=0,"",SUM(AF35:AJ35)) | AM35: =IF(ISERROR(IF($AL35="","",ROUND(($AL35/$AL$10)*$AM$10,2))),"",IF($AL35="","",ROUND(($AL35/$AL$10)*$AM$10,2))) | AN35: =IF($AM35="","",ROUND($AM35*$AN$10,2)) | AO35: =IF(ISERROR(IF($AN35="","",ROUND(SUM($R35,$AE35,$AN35),2))),"",IF($AN35="","",ROUND(SUM($R35,$AE35,$AN35),2))) | AP35: =IF(ISERROR(IF($AO35="","",VLOOKUP(AO35,Table!$B$3:$E$44,4,TRUE))),"",IF($AO35="","",VLOOKUP(AO35,Table!$B$3:$E$44,4,TRUE))) | AQ35: =IF(ISERROR(IF($AP35="","",VLOOKUP(AP35,Table!$H$12:$J$16,3,TRUE))),"",IF($AP35="","",VLOOKUP(AP35,Table!$H$12:$J$16,3,TRUE))) | AR35: =IF(AP35="","",VLOOKUP(ROUND(AP35,0),Table!$H$3:$J$7,3,TRUE))
A36: 25 | B36: ='INPUT DATA'!B36 -> 0 | P36: =IF(COUNT($F36:$O36)=0,"",SUM($F36:$O36)) | Q36: =IF(ISERROR(IF($P36="","",ROUND(($P36/$P$10)*$Q$10,2))),"",IF($P36="","",ROUND(($P36/$P$10)*$Q$10,2))) | R36: =IF($Q36="","",ROUND($Q36*$R$10,2)) | AC36: =IF(COUNT($S36:$AB36)=0,"",SUM($S36:$AB36)) | AD36: =IF(ISERROR(IF($AC36="","",ROUND(($AC36/$AC$10)*$AD$10,2))),"",IF($AC36="","",ROUND(($AC36/$AC$10)*$AD$10,2))) | AE36: =IF($AD36="","",ROUND($AD36*$AE$10,2)) | AL36: =IF(COUNT(AF36:AJ36)=0,"",SUM(AF36:AJ36)) | AM36: =IF(ISERROR(IF($AL36="","",ROUND(($AL36/$AL$10)*$AM$10,2))),"",IF($AL36="","",ROUND(($AL36/$AL$10)*$AM$10,2))) | AN36: =IF($AM36="","",ROUND($AM36*$AN$10,2)) | AO36: =IF(ISERROR(IF($AN36="","",ROUND(SUM($R36,$AE36,$AN36),2))),"",IF($AN36="","",ROUND(SUM($R36,$AE36,$AN36),2))) | AP36: =IF(ISERROR(IF($AO36="","",VLOOKUP(AO36,Table!$B$3:$E$44,4,TRUE))),"",IF($AO36="","",VLOOKUP(AO36,Table!$B$3:$E$44,4,TRUE))) | AQ36: =IF(ISERROR(IF($AP36="","",VLOOKUP(AP36,Table!$H$12:$J$16,3,TRUE))),"",IF($AP36="","",VLOOKUP(AP36,Table!$H$12:$J$16,3,TRUE))) | AR36: =IF(AP36="","",VLOOKUP(ROUND(AP36,0),Table!$H$3:$J$7,3,TRUE))
A37: 26 | B37: ='INPUT DATA'!B37 -> 0 | P37: =IF(COUNT($F37:$O37)=0,"",SUM($F37:$O37)) | Q37: =IF(ISERROR(IF($P37="","",ROUND(($P37/$P$10)*$Q$10,2))),"",IF($P37="","",ROUND(($P37/$P$10)*$Q$10,2))) | R37: =IF($Q37="","",ROUND($Q37*$R$10,2)) | AC37: =IF(COUNT($S37:$AB37)=0,"",SUM($S37:$AB37)) | AD37: =IF(ISERROR(IF($AC37="","",ROUND(($AC37/$AC$10)*$AD$10,2))),"",IF($AC37="","",ROUND(($AC37/$AC$10)*$AD$10,2))) | AE37: =IF($AD37="","",ROUND($AD37*$AE$10,2)) | AL37: =IF(COUNT(AF37:AJ37)=0,"",SUM(AF37:AJ37)) | AM37: =IF(ISERROR(IF($AL37="","",ROUND(($AL37/$AL$10)*$AM$10,2))),"",IF($AL37="","",ROUND(($AL37/$AL$10)*$AM$10,2))) | AN37: =IF($AM37="","",ROUND($AM37*$AN$10,2)) | AO37: =IF(ISERROR(IF($AN37="","",ROUND(SUM($R37,$AE37,$AN37),2))),"",IF($AN37="","",ROUND(SUM($R37,$AE37,$AN37),2))) | AP37: =IF(ISERROR(IF($AO37="","",VLOOKUP(AO37,Table!$B$3:$E$44,4,TRUE))),"",IF($AO37="","",VLOOKUP(AO37,Table!$B$3:$E$44,4,TRUE))) | AQ37: =IF(ISERROR(IF($AP37="","",VLOOKUP(AP37,Table!$H$12:$J$16,3,TRUE))),"",IF($AP37="","",VLOOKUP(AP37,Table!$H$12:$J$16,3,TRUE))) | AR37: =IF(AP37="","",VLOOKUP(ROUND(AP37,0),Table!$H$3:$J$7,3,TRUE))
A38: 27 | B38: ='INPUT DATA'!B38 -> 0 | P38: =IF(COUNT($F38:$O38)=0,"",SUM($F38:$O38)) | Q38: =IF(ISERROR(IF($P38="","",ROUND(($P38/$P$10)*$Q$10,2))),"",IF($P38="","",ROUND(($P38/$P$10)*$Q$10,2))) | R38: =IF($Q38="","",ROUND($Q38*$R$10,2)) | AC38: =IF(COUNT($S38:$AB38)=0,"",SUM($S38:$AB38)) | AD38: =IF(ISERROR(IF($AC38="","",ROUND(($AC38/$AC$10)*$AD$10,2))),"",IF($AC38="","",ROUND(($AC38/$AC$10)*$AD$10,2))) | AE38: =IF($AD38="","",ROUND($AD38*$AE$10,2)) | AL38: =IF(COUNT(AF38:AJ38)=0,"",SUM(AF38:AJ38)) | AM38: =IF(ISERROR(IF($AL38="","",ROUND(($AL38/$AL$10)*$AM$10,2))),"",IF($AL38="","",ROUND(($AL38/$AL$10)*$AM$10,2))) | AN38: =IF($AM38="","",ROUND($AM38*$AN$10,2)) | AO38: =IF(ISERROR(IF($AN38="","",ROUND(SUM($R38,$AE38,$AN38),2))),"",IF($AN38="","",ROUND(SUM($R38,$AE38,$AN38),2))) | AP38: =IF(ISERROR(IF($AO38="","",VLOOKUP(AO38,Table!$B$3:$E$44,4,TRUE))),"",IF($AO38="","",VLOOKUP(AO38,Table!$B$3:$E$44,4,TRUE))) | AQ38: =IF(ISERROR(IF($AP38="","",VLOOKUP(AP38,Table!$H$12:$J$16,3,TRUE))),"",IF($AP38="","",VLOOKUP(AP38,Table!$H$12:$J$16,3,TRUE))) | AR38: =IF(AP38="","",VLOOKUP(ROUND(AP38,0),Table!$H$3:$J$7,3,TRUE))
A39: 28 | B39: ='INPUT DATA'!B39 -> 0 | P39: =IF(COUNT($F39:$O39)=0,"",SUM($F39:$O39)) | Q39: =IF(ISERROR(IF($P39="","",ROUND(($P39/$P$10)*$Q$10,2))),"",IF($P39="","",ROUND(($P39/$P$10)*$Q$10,2))) | R39: =IF($Q39="","",ROUND($Q39*$R$10,2)) | AC39: =IF(COUNT($S39:$AB39)=0,"",SUM($S39:$AB39)) | AD39: =IF(ISERROR(IF($AC39="","",ROUND(($AC39/$AC$10)*$AD$10,2))),"",IF($AC39="","",ROUND(($AC39/$AC$10)*$AD$10,2))) | AE39: =IF($AD39="","",ROUND($AD39*$AE$10,2)) | AL39: =IF(COUNT(AF39:AJ39)=0,"",SUM(AF39:AJ39)) | AM39: =IF(ISERROR(IF($AL39="","",ROUND(($AL39/$AL$10)*$AM$10,2))),"",IF($AL39="","",ROUND(($AL39/$AL$10)*$AM$10,2))) | AN39: =IF($AM39="","",ROUND($AM39*$AN$10,2)) | AO39: =IF(ISERROR(IF($AN39="","",ROUND(SUM($R39,$AE39,$AN39),2))),"",IF($AN39="","",ROUND(SUM($R39,$AE39,$AN39),2))) | AP39: =IF(ISERROR(IF($AO39="","",VLOOKUP(AO39,Table!$B$3:$E$44,4,TRUE))),"",IF($AO39="","",VLOOKUP(AO39,Table!$B$3:$E$44,4,TRUE))) | AQ39: =IF(ISERROR(IF($AP39="","",VLOOKUP(AP39,Table!$H$12:$J$16,3,TRUE))),"",IF($AP39="","",VLOOKUP(AP39,Table!$H$12:$J$16,3,TRUE))) | AR39: =IF(AP39="","",VLOOKUP(ROUND(AP39,0),Table!$H$3:$J$7,3,TRUE))
A40: 29 | B40: ='INPUT DATA'!B40 -> 0 | P40: =IF(COUNT($F40:$O40)=0,"",SUM($F40:$O40)) | Q40: =IF(ISERROR(IF($P40="","",ROUND(($P40/$P$10)*$Q$10,2))),"",IF($P40="","",ROUND(($P40/$P$10)*$Q$10,2))) | R40: =IF($Q40="","",ROUND($Q40*$R$10,2)) | AC40: =IF(COUNT($S40:$AB40)=0,"",SUM($S40:$AB40)) | AD40: =IF(ISERROR(IF($AC40="","",ROUND(($AC40/$AC$10)*$AD$10,2))),"",IF($AC40="","",ROUND(($AC40/$AC$10)*$AD$10,2))) | AE40: =IF($AD40="","",ROUND($AD40*$AE$10,2)) | AL40: =IF(COUNT(AF40:AJ40)=0,"",SUM(AF40:AJ40)) | AM40: =IF(ISERROR(IF($AL40="","",ROUND(($AL40/$AL$10)*$AM$10,2))),"",IF($AL40="","",ROUND(($AL40/$AL$10)*$AM$10,2))) | AN40: =IF($AM40="","",ROUND($AM40*$AN$10,2)) | AO40: =IF(ISERROR(IF($AN40="","",ROUND(SUM($R40,$AE40,$AN40),2))),"",IF($AN40="","",ROUND(SUM($R40,$AE40,$AN40),2))) | AP40: =IF(ISERROR(IF($AO40="","",VLOOKUP(AO40,Table!$B$3:$E$44,4,TRUE))),"",IF($AO40="","",VLOOKUP(AO40,Table!$B$3:$E$44,4,TRUE))) | AQ40: =IF(ISERROR(IF($AP40="","",VLOOKUP(AP40,Table!$H$12:$J$16,3,TRUE))),"",IF($AP40="","",VLOOKUP(AP40,Table!$H$12:$J$16,3,TRUE))) | AR40: =IF(AP40="","",VLOOKUP(ROUND(AP40,0),Table!$H$3:$J$7,3,TRUE))
A41: 30 | B41: ='INPUT DATA'!B41 -> 0 | P41: =IF(COUNT($F41:$O41)=0,"",SUM($F41:$O41)) | Q41: =IF(ISERROR(IF($P41="","",ROUND(($P41/$P$10)*$Q$10,2))),"",IF($P41="","",ROUND(($P41/$P$10)*$Q$10,2))) | R41: =IF($Q41="","",ROUND($Q41*$R$10,2)) | AC41: =IF(COUNT($S41:$AB41)=0,"",SUM($S41:$AB41)) | AD41: =IF(ISERROR(IF($AC41="","",ROUND(($AC41/$AC$10)*$AD$10,2))),"",IF($AC41="","",ROUND(($AC41/$AC$10)*$AD$10,2))) | AE41: =IF($AD41="","",ROUND($AD41*$AE$10,2)) | AL41: =IF(COUNT(AF41:AJ41)=0,"",SUM(AF41:AJ41)) | AM41: =IF(ISERROR(IF($AL41="","",ROUND(($AL41/$AL$10)*$AM$10,2))),"",IF($AL41="","",ROUND(($AL41/$AL$10)*$AM$10,2))) | AN41: =IF($AM41="","",ROUND($AM41*$AN$10,2)) | AO41: =IF(ISERROR(IF($AN41="","",ROUND(SUM($R41,$AE41,$AN41),2))),"",IF($AN41="","",ROUND(SUM($R41,$AE41,$AN41),2))) | AP41: =IF(ISERROR(IF($AO41="","",VLOOKUP(AO41,Table!$B$3:$E$44,4,TRUE))),"",IF($AO41="","",VLOOKUP(AO41,Table!$B$3:$E$44,4,TRUE))) | AQ41: =IF(ISERROR(IF($AP41="","",VLOOKUP(AP41,Table!$H$12:$J$16,3,TRUE))),"",IF($AP41="","",VLOOKUP(AP41,Table!$H$12:$J$16,3,TRUE))) | AR41: =IF(AP41="","",VLOOKUP(ROUND(AP41,0),Table!$H$3:$J$7,3,TRUE))
A42: 31 | B42: ='INPUT DATA'!B42 -> 0 | P42: =IF(COUNT($F42:$O42)=0,"",SUM($F42:$O42)) | Q42: =IF(ISERROR(IF($P42="","",ROUND(($P42/$P$10)*$Q$10,2))),"",IF($P42="","",ROUND(($P42/$P$10)*$Q$10,2))) | R42: =IF($Q42="","",ROUND($Q42*$R$10,2)) | AC42: =IF(COUNT($S42:$AB42)=0,"",SUM($S42:$AB42)) | AD42: =IF(ISERROR(IF($AC42="","",ROUND(($AC42/$AC$10)*$AD$10,2))),"",IF($AC42="","",ROUND(($AC42/$AC$10)*$AD$10,2))) | AE42: =IF($AD42="","",ROUND($AD42*$AE$10,2)) | AL42: =IF(COUNT(AF42:AJ42)=0,"",SUM(AF42:AJ42)) | AM42: =IF(ISERROR(IF($AL42="","",ROUND(($AL42/$AL$10)*$AM$10,2))),"",IF($AL42="","",ROUND(($AL42/$AL$10)*$AM$10,2))) | AN42: =IF($AM42="","",ROUND($AM42*$AN$10,2)) | AO42: =IF(ISERROR(IF($AN42="","",ROUND(SUM($R42,$AE42,$AN42),2))),"",IF($AN42="","",ROUND(SUM($R42,$AE42,$AN42),2))) | AP42: =IF(ISERROR(IF($AO42="","",VLOOKUP(AO42,Table!$B$3:$E$44,4,TRUE))),"",IF($AO42="","",VLOOKUP(AO42,Table!$B$3:$E$44,4,TRUE))) | AQ42: =IF(ISERROR(IF($AP42="","",VLOOKUP(AP42,Table!$H$12:$J$16,3,TRUE))),"",IF($AP42="","",VLOOKUP(AP42,Table!$H$12:$J$16,3,TRUE))) | AR42: =IF(AP42="","",VLOOKUP(ROUND(AP42,0),Table!$H$3:$J$7,3,TRUE))
...

Sheet Term 2
A1: Class Record | AS1: LRN
A3: (Pursuant to Deped Order 8 series of 2015)
C4: REGION | G4: ='INPUT DATA'!G4 -> IX | L4: DIVISION | O4: ='INPUT DATA'!O4 -> Schools Division of Zamboanga del Norte | T4: DISTRICT | X4: ='INPUT DATA'!X4 -> 0
B5: SCHOOL NAME | G5: ='INPUT DATA'!G5 -> 0 | T5: SCHOOL ID | X5: ='INPUT DATA'!X5 -> 0 | AD5: SCHOOL YEAR | AM5: ='INPUT DATA'!AG5 -> 0
A7: Term 1 | F7: GRADE & SECTION: | K7: ='INPUT DATA'!K7 -> 0 | Q7: TEACHER: | S7: ='INPUT DATA'!S7 -> 0 | AC7: SUBJECT: | AM7: ='INPUT DATA'!AG7 -> 0
B8: LEARNERS' NAMES | F8: WRITTEN WORKS (20%) | S8: PERFORMANCE TASKS (60%) | AF8: Summative and Term Examination (20%) | AO8: Initial Grade | AP8: Term Grade | AQ8: Letter Grade | AR8: Descriptive Rating
F9: 1 | G9: 2 | H9: 3 | I9: 4 | J9: 5 | K9: 6 | L9: 7 | M9: 8 | N9: 9 | O9: 10 | P9: Total | Q9: PS | R9: WS | S9: 1 | T9: 2 | U9: 3 | V9: 4 | W9: 5 | X9: 6 | Y9: 7 | Z9: 8 | AA9: 9 | AB9: 10 | AC9: Total | AD9: PS | AE9: WS | AF9: ST1 | AG9: WS1 | AH9: ST2 | AI9: WS2 | AJ9: TE | AK9: WST | AL9: Total | AM9: PS | AN9: WS
B10: HIGHEST POSSIBLE SCORE | P10: =IF(COUNT($F10:$O10)=0,"",SUM($F10:$O10)) | Q10: 100 | R10: 0.2 | AC10: =IF(COUNT($S10:$AB10)=0,"",SUM($S10:$AB10)) | AD10: 100 | AE10: 0.6 | AG10: 30 | AH10: 25 | AI10: 30 | AK10: 40 | AL10: =IF(COUNT(AF10:AJ10)=0,"",SUM(AF10:AJ10)) -> 85 | AM10: 100 | AN10: 0.2
B11: MALE
A12: 1 | B12: ='INPUT DATA'!B12 -> 0 | P12: =IF(COUNT($F12:$O12)=0,"",SUM($F12:$O12)) | Q12: =IF(ISERROR(IF($P12="","",ROUND(($P12/$P$10)*$Q$10,2))),"",IF($P12="","",ROUND(($P12/$P$10)*$Q$10,2))) | R12: =IF($Q12="","",ROUND($Q12*$R$10,2)) | AC12: =IF(COUNT($S12:$AB12)=0,"",SUM($S12:$AB12)) | AD12: =IF(ISERROR(IF($AC12="","",ROUND(($AC12/$AC$10)*$AD$10,2))),"",IF($AC12="","",ROUND(($AC12/$AC$10)*$AD$10,2))) | AE12: =IF($AD12="","",ROUND($AD12*$AE$10,2)) | AG12: =IF(ISBLANK(AF12),"",(AF12/$AF$10)*$AG$10) | AI12: =IF(ISBLANK(AH12),"",(AH12/$AH$10)*$AI$10) | AK12: =IF(ISBLANK(AJ12),"",(AJ12/$AJ$10)*$AK$10) | AL12: =IF(COUNTA(AF12,AH12,AJ12),AF12+AH12+AJ12,"") | AM12: =IFERROR(IF(COUNTA(AG12,AI12,AK12),(AG12+AI12+AK12),""),"") | AN12: =IF($AM12="","",ROUND($AM12*$AN$10,2)) | AO12: =IF(ISERROR(IF($AN12="","",ROUND(SUM($R12,$AE12,$AN12),2))),"",IF($AN12="","",ROUND(SUM($R12,$AE12,$AN12),2))) | AP12: =IF(ISERROR(IF($AO12="","",VLOOKUP(AO12,Table!$B$3:$E$44,4,TRUE))),"",IF($AO12="","",VLOOKUP(AO12,Table!$B$3:$E$44,4,TRUE))) | AQ12: =IF(ISERROR(IF($AP12="","",VLOOKUP(AP12,Table!$H$12:$J$16,3,TRUE))),"",IF($AP12="","",VLOOKUP(AP12,Table!$H$12:$J$16,3,TRUE))) | AR12: =IF(AP12="","",VLOOKUP(ROUND(AP12,0),Table!$H$3:$J$7,3,TRUE)) | AS12: 124623170080
A13: 2 | B13: ='INPUT DATA'!B13 -> 0 | P13: =IF(COUNT($F13:$O13)=0,"",SUM($F13:$O13)) | Q13: =IF(ISERROR(IF($P13="","",ROUND(($P13/$P$10)*$Q$10,2))),"",IF($P13="","",ROUND(($P13/$P$10)*$Q$10,2))) | R13: =IF($Q13="","",ROUND($Q13*$R$10,2)) | AC13: =IF(COUNT($S13:$AB13)=0,"",SUM($S13:$AB13)) | AD13: =IF(ISERROR(IF($AC13="","",ROUND(($AC13/$AC$10)*$AD$10,2))),"",IF($AC13="","",ROUND(($AC13/$AC$10)*$AD$10,2))) | AE13: =IF($AD13="","",ROUND($AD13*$AE$10,2)) | AG13: =IF(ISBLANK(AF13),"",(AF13/$AF$10)*$AG$10) | AI13: =IF(ISBLANK(AH13),"",(AH13/$AH$10)*$AI$10) | AK13: =IF(ISBLANK(AJ13),"",(AJ13/$AJ$10)*$AK$10) | AL13: =IF(COUNTA(AF13,AH13,AJ13),AF13+AH13+AJ13,"") | AM13: =IFERROR(IF(COUNTA(AG13,AI13,AK13),(AG13+AI13+AK13),""),"") | AN13: =IF($AM13="","",ROUND($AM13*$AN$10,2)) | AO13: =IF(ISERROR(IF($AN13="","",ROUND(SUM($R13,$AE13,$AN13),2))),"",IF($AN13="","",ROUND(SUM($R13,$AE13,$AN13),2))) | AP13: =IF(ISERROR(IF($AO13="","",VLOOKUP(AO13,Table!$B$3:$E$44,4,TRUE))),"",IF($AO13="","",VLOOKUP(AO13,Table!$B$3:$E$44,4,TRUE))) | AQ13: =IF(ISERROR(IF($AP13="","",VLOOKUP(AP13,Table!$H$12:$J$16,3,TRUE))),"",IF($AP13="","",VLOOKUP(AP13,Table!$H$12:$J$16,3,TRUE))) | AR13: =IF(AP13="","",VLOOKUP(ROUND(AP13,0),Table!$H$3:$J$7,3,TRUE)) | AS13: 124623170082
A14: 3 | B14: ='INPUT DATA'!B14 -> 0 | P14: =IF(COUNT($F14:$O14)=0,"",SUM($F14:$O14)) | Q14: =IF(ISERROR(IF($P14="","",ROUND(($P14/$P$10)*$Q$10,2))),"",IF($P14="","",ROUND(($P14/$P$10)*$Q$10,2))) | R14: =IF($Q14="","",ROUND($Q14*$R$10,2)) | AC14: =IF(COUNT($S14:$AB14)=0,"",SUM($S14:$AB14)) | AD14: =IF(ISERROR(IF($AC14="","",ROUND(($AC14/$AC$10)*$AD$10,2))),"",IF($AC14="","",ROUND(($AC14/$AC$10)*$AD$10,2))) | AE14: =IF($AD14="","",ROUND($AD14*$AE$10,2)) | AG14: =IF(ISBLANK(AF14),"",(AF14/$AF$10)*$AG$10) | AI14: =IF(ISBLANK(AH14),"",(AH14/$AH$10)*$AI$10) | AK14: =IF(ISBLANK(AJ14),"",(AJ14/$AJ$10)*$AK$10) | AL14: =IF(COUNTA(AF14,AH14,AJ14),AF14+AH14+AJ14,"") | AM14: =IFERROR(IF(COUNTA(AG14,AI14,AK14),(AG14+AI14+AK14),""),"") | AN14: =IF($AM14="","",ROUND($AM14*$AN$10,2)) | AO14: =IF(ISERROR(IF($AN14="","",ROUND(SUM($R14,$AE14,$AN14),2))),"",IF($AN14="","",ROUND(SUM($R14,$AE14,$AN14),2))) | AP14: =IF(ISERROR(IF($AO14="","",VLOOKUP(AO14,Table!$B$3:$E$44,4,TRUE))),"",IF($AO14="","",VLOOKUP(AO14,Table!$B$3:$E$44,4,TRUE))) | AQ14: =IF(ISERROR(IF($AP14="","",VLOOKUP(AP14,Table!$H$12:$J$16,3,TRUE))),"",IF($AP14="","",VLOOKUP(AP14,Table!$H$12:$J$16,3,TRUE))) | AR14: =IF(AP14="","",VLOOKUP(ROUND(AP14,0),Table!$H$3:$J$7,3,TRUE)) | AS14: 124623160139
A15: 4 | B15: ='INPUT DATA'!B15 -> 0 | P15: =IF(COUNT($F15:$O15)=0,"",SUM($F15:$O15)) | Q15: =IF(ISERROR(IF($P15="","",ROUND(($P15/$P$10)*$Q$10,2))),"",IF($P15="","",ROUND(($P15/$P$10)*$Q$10,2))) | R15: =IF($Q15="","",ROUND($Q15*$R$10,2)) | AC15: =IF(COUNT($S15:$AB15)=0,"",SUM($S15:$AB15)) | AD15: =IF(ISERROR(IF($AC15="","",ROUND(($AC15/$AC$10)*$AD$10,2))),"",IF($AC15="","",ROUND(($AC15/$AC$10)*$AD$10,2))) | AE15: =IF($AD15="","",ROUND($AD15*$AE$10,2)) | AG15: =IF(ISBLANK(AF15),"",(AF15/$AF$10)*$AG$10) | AI15: =IF(ISBLANK(AH15),"",(AH15/$AH$10)*$AI$10) | AK15: =IF(ISBLANK(AJ15),"",(AJ15/$AJ$10)*$AK$10) | AL15: =IF(COUNTA(AF15,AH15,AJ15),AF15+AH15+AJ15,"") | AM15: =IFERROR(IF(COUNTA(AG15,AI15,AK15),(AG15+AI15+AK15),""),"") | AN15: =IF($AM15="","",ROUND($AM15*$AN$10,2)) | AO15: =IF(ISERROR(IF($AN15="","",ROUND(SUM($R15,$AE15,$AN15),2))),"",IF($AN15="","",ROUND(SUM($R15,$AE15,$AN15),2))) | AP15: =IF(ISERROR(IF($AO15="","",VLOOKUP(AO15,Table!$B$3:$E$44,4,TRUE))),"",IF($AO15="","",VLOOKUP(AO15,Table!$B$3:$E$44,4,TRUE))) | AQ15: =IF(ISERROR(IF($AP15="","",VLOOKUP(AP15,Table!$H$12:$J$16,3,TRUE))),"",IF($AP15="","",VLOOKUP(AP15,Table!$H$12:$J$16,3,TRUE))) | AR15: =IF(AP15="","",VLOOKUP(ROUND(AP15,0),Table!$H$3:$J$7,3,TRUE)) | AS15: 125785170007
A16: 5 | B16: ='INPUT DATA'!B16 -> 0 | P16: =IF(COUNT($F16:$O16)=0,"",SUM($F16:$O16)) | Q16: =IF(ISERROR(IF($P16="","",ROUND(($P16/$P$10)*$Q$10,2))),"",IF($P16="","",ROUND(($P16/$P$10)*$Q$10,2))) | R16: =IF($Q16="","",ROUND($Q16*$R$10,2)) | AC16: =IF(COUNT($S16:$AB16)=0,"",SUM($S16:$AB16)) | AD16: =IF(ISERROR(IF($AC16="","",ROUND(($AC16/$AC$10)*$AD$10,2))),"",IF($AC16="","",ROUND(($AC16/$AC$10)*$AD$10,2))) | AE16: =IF($AD16="","",ROUND($AD16*$AE$10,2)) | AG16: =IF(ISBLANK(AF16),"",(AF16/$AF$10)*$AG$10) | AI16: =IF(ISBLANK(AH16),"",(AH16/$AH$10)*$AI$10) | AK16: =IF(ISBLANK(AJ16),"",(AJ16/$AJ$10)*$AK$10) | AL16: =IF(COUNTA(AF16,AH16,AJ16),AF16+AH16+AJ16,"") | AM16: =IFERROR(IF(COUNTA(AG16,AI16,AK16),(AG16+AI16+AK16),""),"") | AN16: =IF($AM16="","",ROUND($AM16*$AN$10,2)) | AO16: =IF(ISERROR(IF($AN16="","",ROUND(SUM($R16,$AE16,$AN16),2))),"",IF($AN16="","",ROUND(SUM($R16,$AE16,$AN16),2))) | AP16: =IF(ISERROR(IF($AO16="","",VLOOKUP(AO16,Table!$B$3:$E$44,4,TRUE))),"",IF($AO16="","",VLOOKUP(AO16,Table!$B$3:$E$44,4,TRUE))) | AQ16: =IF(ISERROR(IF($AP16="","",VLOOKUP(AP16,Table!$H$12:$J$16,3,TRUE))),"",IF($AP16="","",VLOOKUP(AP16,Table!$H$12:$J$16,3,TRUE))) | AR16: =IF(AP16="","",VLOOKUP(ROUND(AP16,0),Table!$H$3:$J$7,3,TRUE)) | AS16: 124628170031
A17: 6 | B17: ='INPUT DATA'!B17 -> 0 | P17: =IF(COUNT($F17:$O17)=0,"",SUM($F17:$O17)) | Q17: =IF(ISERROR(IF($P17="","",ROUND(($P17/$P$10)*$Q$10,2))),"",IF($P17="","",ROUND(($P17/$P$10)*$Q$10,2))) | R17: =IF($Q17="","",ROUND($Q17*$R$10,2)) | AC17: =IF(COUNT($S17:$AB17)=0,"",SUM($S17:$AB17)) | AD17: =IF(ISERROR(IF($AC17="","",ROUND(($AC17/$AC$10)*$AD$10,2))),"",IF($AC17="","",ROUND(($AC17/$AC$10)*$AD$10,2))) | AE17: =IF($AD17="","",ROUND($AD17*$AE$10,2)) | AG17: =IF(ISBLANK(AF17),"",(AF17/$AF$10)*$AG$10) | AI17: =IF(ISBLANK(AH17),"",(AH17/$AH$10)*$AI$10) | AK17: =IF(ISBLANK(AJ17),"",(AJ17/$AJ$10)*$AK$10) | AL17: =IF(COUNTA(AF17,AH17,AJ17),AF17+AH17+AJ17,"") | AM17: =IFERROR(IF(COUNTA(AG17,AI17,AK17),(AG17+AI17+AK17),""),"") | AN17: =IF($AM17="","",ROUND($AM17*$AN$10,2)) | AO17: =IF(ISERROR(IF($AN17="","",ROUND(SUM($R17,$AE17,$AN17),2))),"",IF($AN17="","",ROUND(SUM($R17,$AE17,$AN17),2))) | AP17: =IF(ISERROR(IF($AO17="","",VLOOKUP(AO17,Table!$B$3:$E$44,4,TRUE))),"",IF($AO17="","",VLOOKUP(AO17,Table!$B$3:$E$44,4,TRUE))) | AQ17: =IF(ISERROR(IF($AP17="","",VLOOKUP(AP17,Table!$H$12:$J$16,3,TRUE))),"",IF($AP17="","",VLOOKUP(AP17,Table!$H$12:$J$16,3,TRUE))) | AR17: =IF(AP17="","",VLOOKUP(ROUND(AP17,0),Table!$H$3:$J$7,3,TRUE)) | AS17: 12427570007
A18: 7 | B18: ='INPUT DATA'!B18 -> 0 | P18: =IF(COUNT($F18:$O18)=0,"",SUM($F18:$O18)) | Q18: =IF(ISERROR(IF($P18="","",ROUND(($P18/$P$10)*$Q$10,2))),"",IF($P18="","",ROUND(($P18/$P$10)*$Q$10,2))) | R18: =IF($Q18="","",ROUND($Q18*$R$10,2)) | AC18: =IF(COUNT($S18:$AB18)=0,"",SUM($S18:$AB18)) | AD18: =IF(ISERROR(IF($AC18="","",ROUND(($AC18/$AC$10)*$AD$10,2))),"",IF($AC18="","",ROUND(($AC18/$AC$10)*$AD$10,2))) | AE18: =IF($AD18="","",ROUND($AD18*$AE$10,2)) | AG18: =IF(ISBLANK(AF18),"",(AF18/$AF$10)*$AG$10) | AI18: =IF(ISBLANK(AH18),"",(AH18/$AH$10)*$AI$10) | AK18: =IF(ISBLANK(AJ18),"",(AJ18/$AJ$10)*$AK$10) | AL18: =IF(COUNTA(AF18,AH18,AJ18),AF18+AH18+AJ18,"") | AM18: =IFERROR(IF(COUNTA(AG18,AI18,AK18),(AG18+AI18+AK18),""),"") | AN18: =IF($AM18="","",ROUND($AM18*$AN$10,2)) | AO18: =IF(ISERROR(IF($AN18="","",ROUND(SUM($R18,$AE18,$AN18),2))),"",IF($AN18="","",ROUND(SUM($R18,$AE18,$AN18),2))) | AP18: =IF(ISERROR(IF($AO18="","",VLOOKUP(AO18,Table!$B$3:$E$44,4,TRUE))),"",IF($AO18="","",VLOOKUP(AO18,Table!$B$3:$E$44,4,TRUE))) | AQ18: =IF(ISERROR(IF($AP18="","",VLOOKUP(AP18,Table!$H$12:$J$16,3,TRUE))),"",IF($AP18="","",VLOOKUP(AP18,Table!$H$12:$J$16,3,TRUE))) | AR18: =IF(AP18="","",VLOOKUP(ROUND(AP18,0),Table!$H$3:$J$7,3,TRUE)) | AS18: 124625150005
A19: 8 | B19: ='INPUT DATA'!B19 -> 0 | D19: 0 | P19: =IF(COUNT($F19:$O19)=0,"",SUM($F19:$O19)) | Q19: =IF(ISERROR(IF($P19="","",ROUND(($P19/$P$10)*$Q$10,2))),"",IF($P19="","",ROUND(($P19/$P$10)*$Q$10,2))) | R19: =IF($Q19="","",ROUND($Q19*$R$10,2)) | AC19: =IF(COUNT($S19:$AB19)=0,"",SUM($S19:$AB19)) | AD19: =IF(ISERROR(IF($AC19="","",ROUND(($AC19/$AC$10)*$AD$10,2))),"",IF($AC19="","",ROUND(($AC19/$AC$10)*$AD$10,2))) | AE19: =IF($AD19="","",ROUND($AD19*$AE$10,2)) | AG19: =IF(ISBLANK(AF19),"",(AF19/$AF$10)*$AG$10) | AI19: =IF(ISBLANK(AH19),"",(AH19/$AH$10)*$AI$10) | AK19: =IF(ISBLANK(AJ19),"",(AJ19/$AJ$10)*$AK$10) | AL19: =IF(COUNTA(AF19,AH19,AJ19),AF19+AH19+AJ19,"") | AM19: =IFERROR(IF(COUNTA(AG19,AI19,AK19),(AG19+AI19+AK19),""),"") | AN19: =IF($AM19="","",ROUND($AM19*$AN$10,2)) | AO19: =IF(ISERROR(IF($AN19="","",ROUND(SUM($R19,$AE19,$AN19),2))),"",IF($AN19="","",ROUND(SUM($R19,$AE19,$AN19),2))) | AP19: =IF(ISERROR(IF($AO19="","",VLOOKUP(AO19,Table!$B$3:$E$44,4,TRUE))),"",IF($AO19="","",VLOOKUP(AO19,Table!$B$3:$E$44,4,TRUE))) | AQ19: =IF(ISERROR(IF($AP19="","",VLOOKUP(AP19,Table!$H$12:$J$16,3,TRUE))),"",IF($AP19="","",VLOOKUP(AP19,Table!$H$12:$J$16,3,TRUE))) | AR19: =IF(AP19="","",VLOOKUP(ROUND(AP19,0),Table!$H$3:$J$7,3,TRUE)) | AS19: 124628160034
A20: 9 | B20: ='INPUT DATA'!B20 -> 0 | P20: =IF(COUNT($F20:$O20)=0,"",SUM($F20:$O20)) | Q20: =IF(ISERROR(IF($P20="","",ROUND(($P20/$P$10)*$Q$10,2))),"",IF($P20="","",ROUND(($P20/$P$10)*$Q$10,2))) | R20: =IF($Q20="","",ROUND($Q20*$R$10,2)) | AC20: =IF(COUNT($S20:$AB20)=0,"",SUM($S20:$AB20)) | AD20: =IF(ISERROR(IF($AC20="","",ROUND(($AC20/$AC$10)*$AD$10,2))),"",IF($AC20="","",ROUND(($AC20/$AC$10)*$AD$10,2))) | AE20: =IF($AD20="","",ROUND($AD20*$AE$10,2)) | AG20: =IF(ISBLANK(AF20),"",(AF20/$AF$10)*$AG$10) | AI20: =IF(ISBLANK(AH20),"",(AH20/$AH$10)*$AI$10) | AK20: =IF(ISBLANK(AJ20),"",(AJ20/$AJ$10)*$AK$10) | AL20: =IF(COUNTA(AF20,AH20,AJ20),AF20+AH20+AJ20,"") | AM20: =IFERROR(IF(COUNTA(AG20,AI20,AK20),(AG20+AI20+AK20),""),"") | AN20: =IF($AM20="","",ROUND($AM20*$AN$10,2)) | AO20: =IF(ISERROR(IF($AN20="","",ROUND(SUM($R20,$AE20,$AN20),2))),"",IF($AN20="","",ROUND(SUM($R20,$AE20,$AN20),2))) | AP20: =IF(ISERROR(IF($AO20="","",VLOOKUP(AO20,Table!$B$3:$E$44,4,TRUE))),"",IF($AO20="","",VLOOKUP(AO20,Table!$B$3:$E$44,4,TRUE))) | AQ20: =IF(ISERROR(IF($AP20="","",VLOOKUP(AP20,Table!$H$12:$J$16,3,TRUE))),"",IF($AP20="","",VLOOKUP(AP20,Table!$H$12:$J$16,3,TRUE))) | AR20: =IF(AP20="","",VLOOKUP(ROUND(AP20,0),Table!$H$3:$J$7,3,TRUE)) | AS20: 124623150072
A21: 10 | B21: ='INPUT DATA'!B21 -> 0 | P21: =IF(COUNT($F21:$O21)=0,"",SUM($F21:$O21)) | Q21: =IF(ISERROR(IF($P21="","",ROUND(($P21/$P$10)*$Q$10,2))),"",IF($P21="","",ROUND(($P21/$P$10)*$Q$10,2))) | R21: =IF($Q21="","",ROUND($Q21*$R$10,2)) | AC21: =IF(COUNT($S21:$AB21)=0,"",SUM($S21:$AB21)) | AD21: =IF(ISERROR(IF($AC21="","",ROUND(($AC21/$AC$10)*$AD$10,2))),"",IF($AC21="","",ROUND(($AC21/$AC$10)*$AD$10,2))) | AE21: =IF($AD21="","",ROUND($AD21*$AE$10,2)) | AG21: =IF(ISBLANK(AF21),"",(AF21/$AF$10)*$AG$10) | AI21: =IF(ISBLANK(AH21),"",(AH21/$AH$10)*$AI$10) | AK21: =IF(ISBLANK(AJ21),"",(AJ21/$AJ$10)*$AK$10) | AL21: =IF(COUNTA(AF21,AH21,AJ21),AF21+AH21+AJ21,"") | AM21: =IFERROR(IF(COUNTA(AG21,AI21,AK21),(AG21+AI21+AK21),""),"") | AN21: =IF($AM21="","",ROUND($AM21*$AN$10,2)) | AO21: =IF(ISERROR(IF($AN21="","",ROUND(SUM($R21,$AE21,$AN21),2))),"",IF($AN21="","",ROUND(SUM($R21,$AE21,$AN21),2))) | AP21: =IF(ISERROR(IF($AO21="","",VLOOKUP(AO21,Table!$B$3:$E$44,4,TRUE))),"",IF($AO21="","",VLOOKUP(AO21,Table!$B$3:$E$44,4,TRUE))) | AQ21: =IF(ISERROR(IF($AP21="","",VLOOKUP(AP21,Table!$H$12:$J$16,3,TRUE))),"",IF($AP21="","",VLOOKUP(AP21,Table!$H$12:$J$16,3,TRUE))) | AR21: =IF(AP21="","",VLOOKUP(ROUND(AP21,0),Table!$H$3:$J$7,3,TRUE)) | AS21: 124623170177
A22: 11 | B22: ='INPUT DATA'!B22 -> 0 | D22: 0 | P22: =IF(COUNT($F22:$O22)=0,"",SUM($F22:$O22)) | Q22: =IF(ISERROR(IF($P22="","",ROUND(($P22/$P$10)*$Q$10,2))),"",IF($P22="","",ROUND(($P22/$P$10)*$Q$10,2))) | R22: =IF($Q22="","",ROUND($Q22*$R$10,2)) | AC22: =IF(COUNT($S22:$AB22)=0,"",SUM($S22:$AB22)) | AD22: =IF(ISERROR(IF($AC22="","",ROUND(($AC22/$AC$10)*$AD$10,2))),"",IF($AC22="","",ROUND(($AC22/$AC$10)*$AD$10,2))) | AE22: =IF($AD22="","",ROUND($AD22*$AE$10,2)) | AG22: =IF(ISBLANK(AF22),"",(AF22/$AF$10)*$AG$10) | AI22: =IF(ISBLANK(AH22),"",(AH22/$AH$10)*$AI$10) | AK22: =IF(ISBLANK(AJ22),"",(AJ22/$AJ$10)*$AK$10) | AL22: =IF(COUNTA(AF22,AH22,AJ22),AF22+AH22+AJ22,"") | AM22: =IFERROR(IF(COUNTA(AG22,AI22,AK22),(AG22+AI22+AK22),""),"") | AN22: =IF($AM22="","",ROUND($AM22*$AN$10,2)) | AO22: =IF(ISERROR(IF($AN22="","",ROUND(SUM($R22,$AE22,$AN22),2))),"",IF($AN22="","",ROUND(SUM($R22,$AE22,$AN22),2))) | AP22: =IF(ISERROR(IF($AO22="","",VLOOKUP(AO22,Table!$B$3:$E$44,4,TRUE))),"",IF($AO22="","",VLOOKUP(AO22,Table!$B$3:$E$44,4,TRUE))) | AQ22: =IF(ISERROR(IF($AP22="","",VLOOKUP(AP22,Table!$H$12:$J$16,3,TRUE))),"",IF($AP22="","",VLOOKUP(AP22,Table!$H$12:$J$16,3,TRUE))) | AR22: =IF(AP22="","",VLOOKUP(ROUND(AP22,0),Table!$H$3:$J$7,3,TRUE)) | AS22: 124628160014
A23: 12 | B23: ='INPUT DATA'!B23 -> 0 | P23: =IF(COUNT($F23:$O23)=0,"",SUM($F23:$O23)) | Q23: =IF(ISERROR(IF($P23="","",ROUND(($P23/$P$10)*$Q$10,2))),"",IF($P23="","",ROUND(($P23/$P$10)*$Q$10,2))) | R23: =IF($Q23="","",ROUND($Q23*$R$10,2)) | AC23: =IF(COUNT($S23:$AB23)=0,"",SUM($S23:$AB23)) | AD23: =IF(ISERROR(IF($AC23="","",ROUND(($AC23/$AC$10)*$AD$10,2))),"",IF($AC23="","",ROUND(($AC23/$AC$10)*$AD$10,2))) | AE23: =IF($AD23="","",ROUND($AD23*$AE$10,2)) | AG23: =IF(ISBLANK(AF23),"",(AF23/$AF$10)*$AG$10) | AI23: =IF(ISBLANK(AH23),"",(AH23/$AH$10)*$AI$10) | AK23: =IF(ISBLANK(AJ23),"",(AJ23/$AJ$10)*$AK$10) | AL23: =IF(COUNTA(AF23,AH23,AJ23),AF23+AH23+AJ23,"") | AM23: =IFERROR(IF(COUNTA(AG23,AI23,AK23),(AG23+AI23+AK23),""),"") | AN23: =IF($AM23="","",ROUND($AM23*$AN$10,2)) | AO23: =IF(ISERROR(IF($AN23="","",ROUND(SUM($R23,$AE23,$AN23),2))),"",IF($AN23="","",ROUND(SUM($R23,$AE23,$AN23),2))) | AP23: =IF(ISERROR(IF($AO23="","",VLOOKUP(AO23,Table!$B$3:$E$44,4,TRUE))),"",IF($AO23="","",VLOOKUP(AO23,Table!$B$3:$E$44,4,TRUE))) | AQ23: =IF(ISERROR(IF($AP23="","",VLOOKUP(AP23,Table!$H$12:$J$16,3,TRUE))),"",IF($AP23="","",VLOOKUP(AP23,Table!$H$12:$J$16,3,TRUE))) | AR23: =IF(AP23="","",VLOOKUP(ROUND(AP23,0),Table!$H$3:$J$7,3,TRUE)) | AS23: 124616170003
